Workbook
Name Excel_BuiltIn__FilterDatabase: Вторник!$A$1:$H$65497
Name Excel_BuiltIn__FilterDatabase: ПН!$B$2:$D$47
Name Excel_BuiltIn__FilterDatabase: Понедельник!$A$1:$I$151

Sheet Неделя
A1: Велес гоголя 180 | B1: 2.07 | C1: 1 | H1: 5 | I1: 1 | J1: 1 | K1: 1 | L1: 1 | M1: 1 | N1: =SUM(I1:M1)-H1 -> 0 | O1: =I1*B1 -> 2.07 | P1: =J1*B1 -> 2.07 | Q1: =K1*B1 -> 2.07 | R1: =L1*B1 -> 2.07 | S1: =M1*B1 -> 2.07
A2: Велес красина 180 | B2: 2.07 | C2: 1 | H2: 5 | I2: 1 | J2: 1 | K2: 1 | L2: 1 | M2: 1 | N2: =SUM(I2:M2)-H2 -> 0 | O2: =I2*B2 -> 2.07 | P2: =J2*B2 -> 2.07 | Q2: =K2*B2 -> 2.07 | R2: =L2*B2 -> 2.07 | S2: =M2*B2 -> 2.07
A3: департамент финансов советская 66-150 резаный | B3: 1.275 | D3: 1 | H3: 5 | I3: 1 | J3: 1 | K3: 1 | L3: 1 | M3: 1 | N3: =SUM(I3:M3)-H3 -> 0 | O3: =I3*B3 -> 1.275 | P3: =J3*B3 -> 1.275 | Q3: =K3*B3 -> 1.275 | R3: =L3*B3 -> 1.275 | S3: =M3*B3 -> 1.275
A4: метрополис к. Маркса -2x180, 2x150 | B4: =4.14+2.55 -> 6.69 | C4: 2 | D4: 2 | H4: 5 | I4: 1 | J4: 1 | K4: 1 | L4: 1 | M4: 1 | N4: =SUM(I4:M4)-H4 -> 0 | O4: =I4*B4 -> 6.69 | P4: =J4*B4 -> 6.69 | Q4: =K4*B4 -> 6.69 | R4: =L4*B4 -> 6.69 | S4: =M4*B4 -> 6.69
A5: метрополис Москва-2х180 | B5: 4.14 | C5: 2 | H5: 5 | I5: 1 | J5: 1 | K5: 1 | L5: 1 | M5: 1 | N5: =SUM(I5:M5)-H5 -> 0 | O5: =I5*B5 -> 4.14 | P5: =J5*B5 -> 4.14 | Q5: =K5*B5 -> 4.14 | R5: =L5*B5 -> 4.14 | S5: =M5*B5 -> 4.14
A6: МТС ленина 6 180 | B6: 2.07 | C6: 1 | H6: 5 | I6: 1 | J6: 1 | K6: 1 | L6: 1 | M6: 1 | N6: =SUM(I6:M6)-H6 -> 0 | O6: =I6*B6 -> 2.07 | P6: =J6*B6 -> 2.07 | Q6: =K6*B6 -> 2.07 | R6: =L6*B6 -> 2.07 | S6: =M6*B6 -> 2.07
A7: пальмира Ленина 5- 200 новый 150 нов | B7: =2.07+1.275 -> 3.345 | C7: 1 | D7: 1 | H7: 5 | I7: 1 | J7: 1 | K7: 1 | L7: 1 | M7: 1 | N7: =SUM(I7:M7)-H7 -> 0 | O7: =I7*B7 -> 3.345 | P7: =J7*B7 -> 3.345 | Q7: =K7*B7 -> 3.345 | R7: =L7*B7 -> 3.345 | S7: =M7*B7 -> 3.345
A8: чунунок к. Мяготина-2x180 | B8: 4.14 | C8: 2 | H8: 5 | I8: 1 | J8: 1 | K8: 1 | L8: 1 | M8: 1 | N8: =SUM(I8:M8)-H8 -> 0 | O8: =I8*B8 -> 4.14 | P8: =J8*B8 -> 4.14 | Q8: =K8*B8 -> 4.14 | R8: =L8*B8 -> 4.14 | S8: =M8*B8 -> 4.14
A9: Сбер академия 2х150 коричнев стар | B9: 2.55 | D9: 2 | H9: 4 | I9: 1 | J9: 1 | K9: 1 | L9: 1 | N9: =SUM(I9:M9)-H9 -> 0 | O9: =I9*B9 -> 2.55 | P9: =J9*B9 -> 2.55 | Q9: =K9*B9 -> 2.55 | R9: =L9*B9 -> 2.55 | S9: =M9*B9 -> 0
A10: Сбер красина 2х150 | B10: 2.55 | D10: 2 | H10: 4 | I10: 1 | J10: 1 | K10: 1 | L10: 1 | N10: =SUM(I10:M10)-H10 -> 0 | O10: =I10*B10 -> 2.55 | P10: =J10*B10 -> 2.55 | Q10: =K10*B10 -> 2.55 | R10: =L10*B10 -> 2.55 | S10: =M10*B10 -> 0
A11: сбербанк гоголя 98-3ий вход 1 х 150 | B11: =1*1.275 -> 1.275 | C11: 2 | D11: 5 | H11: 3 | I11: 1 | J11: 1 | K11: 1 | N11: =SUM(I11:M11)-H11 -> 0 | O11: =I11*B11 -> 1.275 | P11: =J11*B11 -> 1.275 | Q11: =K11*B11 -> 1.275 | R11: =L11*B11 -> 0 | S11: =M11*B11 -> 0
A12: сбербанк гоголя103- 2х150 коричневые | B12: 2.55 | D12: 2 | H12: 4 | I12: 1 | J12: 1 | K12: 1 | L12: 1 | N12: =SUM(I12:M12)-H12 -> 0 | O12: =I12*B12 -> 2.55 | P12: =J12*B12 -> 2.55 | Q12: =K12*B12 -> 2.55 | R12: =L12*B12 -> 2.55 | S12: =M12*B12 -> 0
A13: Велес дзержинского 180 | B13: 2.07 | C13: 1 | H13: 3 | I13: 1 | K13: 1 | M13: 1 | N13: =SUM(I13:M13)-H13 -> 0 | O13: =I13*B13 -> 2.07 | P13: =J13*B13 -> 0 | Q13: =K13*B13 -> 2.07 | R13: =L13*B13 -> 0 | S13: =M13*B13 -> 2.07
A14: велес юбилейный-150 новый | B14: 1.275 | D14: 1 | H14: 3 | I14: 1 | K14: 1 | M14: 1 | N14: =SUM(I14:M14)-H14 -> 0 | O14: =I14*B14 -> 1.275 | P14: =J14*B14 -> 0 | Q14: =K14*B14 -> 1.275 | R14: =L14*B14 -> 0 | S14: =M14*B14 -> 1.275
A15: газпроммежрегионгаз- 2x150, 180 | B15: =2.55+2.07 -> 4.62 | C15: 1 | H15: 3 | I15: 1 | K15: 1 | M15: 1 | N15: =SUM(I15:M15)-H15 -> 0 | O15: =I15*B15 -> 4.62 | P15: =J15*B15 -> 0 | Q15: =K15*B15 -> 4.62 | R15: =L15*B15 -> 0 | S15: =M15*B15 -> 4.62
A16: Кижк 400 рез, 180 | B16: =4+2.07 -> 6.07 | C16: 1 | F16: 1 | H16: 3 | I16: 1 | K16: 1 | M16: 1 | N16: =SUM(I16:M16)-H16 -> 0 | O16: =I16*B16 -> 6.07 | P16: =J16*B16 -> 0 | Q16: =K16*B16 -> 6.07 | R16: =L16*B16 -> 0 | S16: =M16*B16 -> 6.07
A17: кодак Кирова-150 старые | B17: 1.275 | D17: 1 | H17: 3 | I17: 1 | K17: 1 | M17: 1 | N17: =SUM(I17:M17)-H17 -> 0 | O17: =I17*B17 -> 1.275 | P17: =J17*B17 -> 0 | Q17: =K17*B17 -> 1.275 | R17: =L17*B17 -> 0 | S17: =M17*B17 -> 1.275
A18: мегаблин гоголя-180 | B18: 2.07 | C18: 1 | H18: 3 | I18: 1 | K18: 1 | M18: 1 | N18: =SUM(I18:M18)-H18 -> 0 | O18: =I18*B18 -> 2.07 | P18: =J18*B18 -> 0 | Q18: =K18*B18 -> 2.07 | R18: =L18*B18 -> 0 | S18: =M18*B18 -> 2.07
A19: Монетка гоголя 103 -180 | B19: 2.07 | C19: 1 | H19: 3 | I19: 1 | K19: 1 | M19: 1 | N19: =SUM(I19:M19)-H19 -> 0 | O19: =I19*B19 -> 2.07 | P19: =J19*B19 -> 0 | Q19: =K19*B19 -> 2.07 | R19: =L19*B19 -> 0 | S19: =M19*B19 -> 2.07
A20: Монетка кирова 180 | B20: 2.07 | C20: 1 | H20: 3 | I20: 1 | K20: 1 | M20: 1 | N20: =SUM(I20:M20)-H20 -> 0 | O20: =I20*B20 -> 2.07 | P20: =J20*B20 -> 0 | Q20: =K20*B20 -> 2.07 | R20: =L20*B20 -> 0 | S20: =M20*B20 -> 2.07
A21: Монетка красина 180 | B21: 2.07 | C21: 1 | H21: 3 | I21: 1 | K21: 1 | M21: 1 | N21: =SUM(I21:M21)-H21 -> 0 | O21: =I21*B21 -> 2.07 | P21: =J21*B21 -> 0 | Q21: =K21*B21 -> 2.07 | R21: =L21*B21 -> 0 | S21: =M21*B21 -> 2.07
A22: Монетка пушкина 49-180 | B22: 2.07 | C22: 1 | H22: 3 | I22: 1 | K22: 1 | M22: 1 | N22: =SUM(I22:M22)-H22 -> 0 | O22: =I22*B22 -> 2.07 | P22: =J22*B22 -> 0 | Q22: =K22*B22 -> 2.07 | R22: =L22*B22 -> 0 | S22: =M22*B22 -> 2.07
A23: Монтка Ленина М Горько 180 | B23: 2.07 | C23: 1 | H23: 3 | I23: 1 | K23: 1 | M23: 1 | N23: =SUM(I23:M23)-H23 -> 0 | O23: =I23*B23 -> 2.07 | P23: =J23*B23 -> 0 | Q23: =K23*B23 -> 2.07 | R23: =L23*B23 -> 0 | S23: =M23*B23 -> 2.07
A24: Мясной к. маркса 150 рез | B24: 1.275 | D24: 1 | H24: 3 | I24: 1 | K24: 1 | M24: 1 | N24: =SUM(I24:M24)-H24 -> 0 | O24: =I24*B24 -> 1.275 | P24: =J24*B24 -> 0 | Q24: =K24*B24 -> 1.275 | R24: =L24*B24 -> 0 | S24: =M24*B24 -> 1.275
A25: Мясной советская 39 180 | B25: 2.07 | C25: 1 | H25: 3 | I25: 1 | K25: 1 | M25: 1 | N25: =SUM(I25:M25)-H25 -> 0 | O25: =I25*B25 -> 2.07 | P25: =J25*B25 -> 0 | Q25: =K25*B25 -> 2.07 | R25: =L25*B25 -> 0 | S25: =M25*B25 -> 2.07
A26: Пальмира гоголя 150 | B26: 1.275 | D26: 1 | H26: 3 | I26: 1 | K26: 1 | M26: 1 | N26: =SUM(I26:M26)-H26 -> 0 | O26: =I26*B26 -> 1.275 | P26: =J26*B26 -> 0 | Q26: =K26*B26 -> 1.275 | R26: =L26*B26 -> 0 | S26: =M26*B26 -> 1.275
A27: пальмира юбилейный-180 НОВЫЙ | B27: 2.07 | C27: 1 | H27: 3 | I27: 1 | K27: 1 | M27: 1 | N27: =SUM(I27:M27)-H27 -> 0 | O27: =I27*B27 -> 2.07 | P27: =J27*B27 -> 0 | Q27: =K27*B27 -> 2.07 | R27: =L27*B27 -> 0 | S27: =M27*B27 -> 2.07
A28: прогресс Пролетарская-180, 60x80 | B28: =2.07+1.275 -> 3.345 | C28: 1 | E28: 1 | H28: 3 | I28: 1 | K28: 1 | M28: 1 | N28: =SUM(I28:M28)-H28 -> 0 | O28: =I28*B28 -> 3.345 | P28: =J28*B28 -> 0 | Q28: =K28*B28 -> 3.345 | R28: =L28*B28 -> 0 | S28: =M28*B28 -> 3.345
A29: прогресс советская 180, 150 новые | B29: =2.07+1.275 -> 3.345 | C29: 1 | D29: 1 | H29: 3 | I29: 1 | K29: 1 | M29: 1 | N29: =SUM(I29:M29)-H29 -> 0 | O29: =I29*B29 -> 3.345 | P29: =J29*B29 -> 0 | Q29: =K29*B29 -> 3.345 | R29: =L29*B29 -> 0 | S29: =M29*B29 -> 3.345
A30: сбербанк гоголя 98-1 вх 3Х150 коричневые | B30: =3*1.275 -> 3.825 | H30: 4 | I30: 1 | J30: 1 | K30: 1 | L30: 1 | N30: =SUM(I30:M30)-H30 -> 0 | O30: =I30*B30 -> 3.825 | P30: =J30*B30 -> 3.825 | Q30: =K30*B30 -> 3.825 | R30: =L30*B30 -> 3.825 | S30: =M30*B30 -> 0
A31: сбербанк гоголя 98-2ой вход 2х180 | B31: =2*2.07 -> 4.14 | H31: 3 | I31: 1 | J31: 1 | K31: 1 | N31: =SUM(I31:M31)-H31 -> 0 | O31: =I31*B31 -> 4.14 | P31: =J31*B31 -> 4.14 | Q31: =K31*B31 -> 4.14 | R31: =L31*B31 -> 0 | S31: =M31*B31 -> 0
A32: теремок Куйбышева -150 старый | B32: 1.275 | D32: 1 | H32: 3 | I32: 1 | K32: 1 | M32: 1 | N32: =SUM(I32:M32)-H32 -> 0 | O32: =I32*B32 -> 1.275 | P32: =J32*B32 -> 0 | Q32: =K32*B32 -> 1.275 | R32: =L32*B32 -> 0 | S32: =M32*B32 -> 1.275
A33: Тп 2х180 | B33: 4.14 | C33: 2 | H33: 3 | I33: 1 | K33: 1 | M33: 1 | N33: =SUM(I33:M33)-H33 -> 0 | O33: =I33*B33 -> 4.14 | P33: =J33*B33 -> 0 | Q33: =K33*B33 -> 4.14 | R33: =L33*B33 -> 0 | S33: =M33*B33 -> 4.14
A34: Хлеб да мясо 150 резаный хороший | B34: 1.275 | D34: 1 | H34: 3 | I34: 1 | K34: 1 | M34: 1 | N34: =SUM(I34:M34)-H34 -> 0 | O34: =I34*B34 -> 1.275 | P34: =J34*B34 -> 0 | Q34: =K34*B34 -> 1.275 | R34: =L34*B34 -> 0 | S34: =M34*B34 -> 1.275
A35: Яхонт ленина 150 | B35: 1.275 | D35: 1 | H35: 3 | I35: 1 | K35: 1 | M35: 1 | N35: =SUM(I35:M35)-H35 -> 0 | O35: =I35*B35 -> 1.275 | P35: =J35*B35 -> 0 | Q35: =K35*B35 -> 1.275 | R35: =L35*B35 -> 0 | S35: =M35*B35 -> 1.275
A36: Авангард банк красина 180 сер. 1 шт | B36: 2.07 | C36: 1 | H36: 2 | J36: 1 | M36: 1 | N36: =SUM(I36:M36)-H36 -> 0 | O36: =I36*B36 -> 0 | P36: =J36*B36 -> 2.07 | Q36: =K36*B36 -> 0 | R36: =L36*B36 -> 0 | S36: =M36*B36 -> 2.07
A37: Альфа банк гоголя 180 | B37: 2.07 | C37: 1 | H37: 2 | I37: 1 | L37: 1 | N37: =SUM(I37:M37)-H37 -> 0 | O37: =I37*B37 -> 2.07 | P37: =J37*B37 -> 0 | Q37: =K37*B37 -> 0 | R37: =L37*B37 -> 2.07 | S37: =M37*B37 -> 0
A38: Альфа банк Гоголя-красина 150 сер.нов.1 шт. | B38: 1.275 | D38: 1 | H38: 2 | J38: 1 | M38: 1 | N38: =SUM(I38:M38)-H38 -> 0 | O38: =I38*B38 -> 0 | P38: =J38*B38 -> 1.275 | Q38: =K38*B38 -> 0 | R38: =L38*B38 -> 0 | S38: =M38*B38 -> 1.275
A39: Альфа мед гоголя-2х180 | B39: 4.14 | C39: 2 | H39: 2 | I39: 1 | L39: 1 | N39: =SUM(I39:M39)-H39 -> 0 | O39: =I39*B39 -> 4.14 | P39: =J39*B39 -> 0 | Q39: =K39*B39 -> 0 | R39: =L39*B39 -> 4.14 | S39: =M39*B39 -> 0
A40: Альфа мед к.маркса -2х180,(ц.зд. Женщины, кометология) | B40: 4.14 | C40: 2 | H40: 2 | J40: 1 | M40: 1 | N40: =SUM(I40:M40)-H40 -> 0 | O40: =I40*B40 -> 0 | P40: =J40*B40 -> 4.14 | Q40: =K40*B40 -> 0 | R40: =L40*B40 -> 0 | S40: =M40*B40 -> 4.14
...

Sheet Понедельник
A1: =Неделя!A1 -> Велес гоголя 180 | B1: =Неделя!B1 -> 2.07 | C1: =Неделя!C1 -> 1 | D1: =Неделя!D1 -> 0 | E1: =Неделя!E1 -> 0 | F1: =Неделя!F1 -> 0 | G1: =Неделя!G1 -> 0 | H1: =Неделя!I1 -> 1 | I1: =Неделя!O1 -> 2.07
A2: =Неделя!A2 -> Велес красина 180 | B2: =Неделя!B2 -> 2.07 | C2: =Неделя!C2 -> 1 | D2: =Неделя!D2 -> 0 | E2: =Неделя!E2 -> 0 | F2: =Неделя!F2 -> 0 | G2: =Неделя!G2 -> 0 | H2: =Неделя!I2 -> 1 | I2: =Неделя!O2 -> 2.07
A3: =Неделя!A3 -> департамент финансов советская 66-150 резаный | B3: =Неделя!B3 -> 1.275 | C3: =Неделя!C3 -> 0 | D3: =Неделя!D3 -> 1 | E3: =Неделя!E3 -> 0 | F3: =Неделя!F3 -> 0 | G3: =Неделя!G3 -> 0 | H3: =Неделя!I3 -> 1 | I3: =Неделя!O3 -> 1.275
A4: =Неделя!A4 -> метрополис к. Маркса -2x180, 2x150 | B4: =Неделя!B4 -> 6.69 | C4: =Неделя!C4 -> 2 | D4: =Неделя!D4 -> 2 | E4: =Неделя!E4 -> 0 | F4: =Неделя!F4 -> 0 | G4: =Неделя!G4 -> 0 | H4: =Неделя!I4 -> 1 | I4: =Неделя!O4 -> 6.69
A5: =Неделя!A5 -> метрополис Москва-2х180 | B5: =Неделя!B5 -> 4.14 | C5: =Неделя!C5 -> 2 | D5: =Неделя!D5 -> 0 | E5: =Неделя!E5 -> 0 | F5: =Неделя!F5 -> 0 | G5: =Неделя!G5 -> 0 | H5: =Неделя!I5 -> 1 | I5: =Неделя!O5 -> 4.14
A6: =Неделя!A6 -> МТС ленина 6 180 | B6: =Неделя!B6 -> 2.07 | C6: =Неделя!C6 -> 1 | D6: =Неделя!D6 -> 0 | E6: =Неделя!E6 -> 0 | F6: =Неделя!F6 -> 0 | G6: =Неделя!G6 -> 0 | H6: =Неделя!I6 -> 1 | I6: =Неделя!O6 -> 2.07
A7: =Неделя!A7 -> пальмира Ленина 5- 200 новый 150 нов | B7: =Неделя!B7 -> 3.345 | C7: =Неделя!C7 -> 1 | D7: =Неделя!D7 -> 1 | E7: =Неделя!E7 -> 0 | F7: =Неделя!F7 -> 0 | G7: =Неделя!G7 -> 0 | H7: =Неделя!I7 -> 1 | I7: =Неделя!O7 -> 3.345
A8: =Неделя!A8 -> чунунок к. Мяготина-2x180 | B8: =Неделя!B8 -> 4.14 | C8: =Неделя!C8 -> 2 | D8: =Неделя!D8 -> 0 | E8: =Неделя!E8 -> 0 | F8: =Неделя!F8 -> 0 | G8: =Неделя!G8 -> 0 | H8: =Неделя!I8 -> 1 | I8: =Неделя!O8 -> 4.14
A9: =Неделя!A9 -> Сбер академия 2х150 коричнев стар | B9: =Неделя!B9 -> 2.55 | C9: =Неделя!C9 -> 0 | D9: =Неделя!D9 -> 2 | E9: =Неделя!E9 -> 0 | F9: =Неделя!F9 -> 0 | G9: =Неделя!G9 -> 0 | H9: =Неделя!I9 -> 1 | I9: =Неделя!O9 -> 2.55
A10: =Неделя!A10 -> Сбер красина 2х150 | B10: =Неделя!B10 -> 2.55 | C10: =Неделя!C10 -> 0 | D10: =Неделя!D10 -> 2 | E10: =Неделя!E10 -> 0 | F10: =Неделя!F10 -> 0 | G10: =Неделя!G10 -> 0 | H10: =Неделя!I10 -> 1 | I10: =Неделя!O10 -> 2.55
A11: =Неделя!A11 -> сбербанк гоголя 98-3ий вход 1 х 150 | B11: =Неделя!B11 -> 1.275 | C11: =Неделя!C11 -> 2 | D11: =Неделя!D11 -> 5 | E11: =Неделя!E11 -> 0 | F11: =Неделя!F11 -> 0 | G11: =Неделя!G11 -> 0 | H11: =Неделя!I11 -> 1 | I11: =Неделя!O11 -> 1.275
A12: =Неделя!A12 -> сбербанк гоголя103- 2х150 коричневые | B12: =Неделя!B12 -> 2.55 | C12: =Неделя!C12 -> 0 | D12: =Неделя!D12 -> 2 | E12: =Неделя!E12 -> 0 | F12: =Неделя!F12 -> 0 | G12: =Неделя!G12 -> 0 | H12: =Неделя!I12 -> 1 | I12: =Неделя!O12 -> 2.55
... A152: =Неделя!A152 -> SoupRamen 180 | B152: =Неделя!B152 -> 2.07 | C152: =Неделя!C152 -> 1 | D152: =Неделя!D152 -> 0 | E152: =Неделя!E152 -> 0 | F152: =Неделя!F152 -> 0 | G152: =Неделя!G152 -> 0 | H152: =Неделя!I152 -> 0 | I152: =Неделя!O152 -> 0
A153: =Неделя!A154 -> 0 | B153: =SUBTOTAL(9,B1:B152) -> 147.23 | C153: =Неделя!C154 -> 180 | D153: =Неделя!D154 -> 150 | E153: =Неделя!E154 -> рез | F153: =Неделя!F154 -> 400 | G153: =Неделя!G154 -> 250 | H153: =Неделя!I154 -> пн | I153: =Неделя!O154 -> пн
A154: =Неделя!A155 -> 0 | B154: =Неделя!B155 -> 98.51 | C154: =Неделя!C155 -> 180 | D154: =Неделя!D155 -> 150 | E154: =Неделя!E155 -> рез | F154: =Неделя!F155 -> 400 | G154: =Неделя!G155 -> 250 | H154: =Неделя!I155 -> 0 | I154: =Неделя!O155 -> 147.23
A155: =Неделя!A156 -> 0 | B155: =Неделя!B156 -> 0 | C155: =Неделя!C156 -> 28 | D155: =Неделя!D156 -> 23 | E155: =Неделя!E156 -> 3 | F155: =Неделя!F156 -> 1 | G155: =Неделя!G156 -> 1 | H155: =Неделя!I156 -> 0 | I155: =Неделя!O156 -> 0
A156: =Неделя!A157 -> 0 | B156: =Неделя!B157 -> 0 | C156: =Неделя!C157 -> 0 | D156: =Неделя!D157 -> 0 | E156: =Неделя!E157 -> 0 | F156: =Неделя!F157 -> 0 | G156: =Неделя!G157 -> 0 | H156: =Неделя!I157 -> 0 | I156: =Неделя!O157 -> 0
A157: =Неделя!A158 -> 0 | B157: =Неделя!B158 -> 0 | C157: =Неделя!C158 -> 0 | D157: =Неделя!D158 -> 0 | E157: =Неделя!E158 -> 0 | F157: =Неделя!F158 -> 0 | G157: =Неделя!G158 -> 0 | H157: =Неделя!I158 -> 0 | I157: =Неделя!O158 -> 0
A158: =Неделя!A159 -> 0 | B158: =Неделя!B159 -> 0 | C158: =Неделя!C159 -> 0 | D158: =Неделя!D159 -> 0 | E158: =Неделя!E159 -> 0 | F158: =Неделя!F159 -> 0 | G158: =Неделя!G159 -> 0 | H158: =Неделя!I159 -> 0 | I158: =Неделя!O159 -> 0
A159: =Неделя!A160 -> 0 | B159: =Неделя!B160 -> 0 | C159: =Неделя!C160 -> 0 | D159: =Неделя!D160 -> 0 | E159: =Неделя!E160 -> 0 | F159: =Неделя!F160 -> 0 | G159: =Неделя!G160 -> 0 | H159: =Неделя!I160 -> 0 | I159: =Неделя!O160 -> 0
A160: =Неделя!A161 -> 0 | B160: =Неделя!B161 -> 0 | C160: =Неделя!C161 -> 0 | D160: =Неделя!D161 -> 0 | E160: =Неделя!E161 -> 0 | F160: =Неделя!F161 -> 0 | G160: =Неделя!G161 -> 0 | H160: =Неделя!I161 -> 0 | I160: =Неделя!O161 -> 0
A161: =Неделя!A162 -> 0 | B161: =Неделя!B162 -> 0 | C161: =Неделя!C162 -> 0 | D161: =Неделя!D162 -> 0 | E161: =Неделя!E162 -> 0 | F161: =Неделя!F162 -> 0 | G161: =Неделя!G162 -> 0 | H161: =Неделя!I162 -> 0 | I161: =Неделя!O162 -> 0
A162: =Неделя!A163 -> 0 | B162: =Неделя!B163 -> 0 | C162: =Неделя!C163 -> 0 | D162: =Неделя!D163 -> 0 | E162: =Неделя!E163 -> 0 | F162: =Неделя!F163 -> 0 | G162: =Неделя!G163 -> 0 | H162: =Неделя!I163 -> 0 | I162: =Неделя!O163 -> 0
A163: =Неделя!A164 -> 0 | B163: =Неделя!B164 -> 0 | C163: =Неделя!C164 -> 0 | D163: =Неделя!D164 -> 0 | E163: =Неделя!E164 -> 0 | F163: =Неделя!F164 -> 0 | G163: =Неделя!G164 -> 0 | H163: =Неделя!I164 -> 0 | I163: =Неделя!O164 -> 0
A164: =Неделя!A165 -> 0 | B164: =Неделя!B165 -> 0 | C164: =Неделя!C165 -> 0 | D164: =Неделя!D165 -> 0 | E164: =Неделя!E165 -> 0 | F164: =Неделя!F165 -> 0 | G164: =Неделя!G165 -> 0 | H164: =Неделя!I165 -> 0 | I164: =Неделя!O165 -> 0
A165: =Неделя!A166 -> 0 | B165: =Неделя!B166 -> 0 | C165: =Неделя!C166 -> 0 | D165: =Неделя!D166 -> 0 | E165: =Неделя!E166 -> 0 | F165: =Неделя!F166 -> 0 | G165: =Неделя!G166 -> 0 | H165: =Неделя!I166 -> 0 | I165: =Неделя!O166 -> 0
... A180: =Неделя!A181 -> 0 | B180: =Неделя!B181 -> 0 | C180: =Неделя!C181 -> 0 | D180: =Неделя!D181 -> 0 | E180: =Неделя!E181 -> 0 | F180: =Неделя!F181 -> 0 | G180: =Неделя!G181 -> 0 | H180: =Неделя!I181 -> 0 | I180: =Неделя!O181 -> 0
C181: =SUBTOTAL(9,C1:C152) -> 44

Sheet Вторник
A1: =Неделя!A1 -> Велес гоголя 180 | B1: =Неделя!B1 -> 2.07 | C1: =Неделя!C1 -> 1 | D1: =Неделя!D1 -> 0 | E1: =Неделя!E1 -> 0 | F1: =Неделя!F1 -> 0 | G1: =Неделя!G1 -> 0 | H1: =Неделя!J1 -> 1
A2: =Неделя!A2 -> Велес красина 180 | B2: =Неделя!B2 -> 2.07 | C2: =Неделя!C2 -> 1 | D2: =Неделя!D2 -> 0 | E2: =Неделя!E2 -> 0 | F2: =Неделя!F2 -> 0 | G2: =Неделя!G2 -> 0 | H2: =Неделя!J2 -> 1
A3: =Неделя!A3 -> департамент финансов советская 66-150 резаный | B3: =Неделя!B3 -> 1.275 | C3: =Неделя!C3 -> 0 | D3: =Неделя!D3 -> 1 | E3: =Неделя!E3 -> 0 | F3: =Неделя!F3 -> 0 | G3: =Неделя!G3 -> 0 | H3: =Неделя!J3 -> 1
A4: =Неделя!A4 -> метрополис к. Маркса -2x180, 2x150 | B4: =Неделя!B4 -> 6.69 | C4: =Неделя!C4 -> 2 | D4: =Неделя!D4 -> 2 | E4: =Неделя!E4 -> 0 | F4: =Неделя!F4 -> 0 | G4: =Неделя!G4 -> 0 | H4: =Неделя!J4 -> 1
A5: =Неделя!A5 -> метрополис Москва-2х180 | B5: =Неделя!B5 -> 4.14 | C5: =Неделя!C5 -> 2 | D5: =Неделя!D5 -> 0 | E5: =Неделя!E5 -> 0 | F5: =Неделя!F5 -> 0 | G5: =Неделя!G5 -> 0 | H5: =Неделя!J5 -> 1
A6: =Неделя!A6 -> МТС ленина 6 180 | B6: =Неделя!B6 -> 2.07 | C6: =Неделя!C6 -> 1 | D6: =Неделя!D6 -> 0 | E6: =Неделя!E6 -> 0 | F6: =Неделя!F6 -> 0 | G6: =Неделя!G6 -> 0 | H6: =Неделя!J6 -> 1
A7: =Неделя!A7 -> пальмира Ленина 5- 200 новый 150 нов | B7: =Неделя!B7 -> 3.345 | C7: =Неделя!C7 -> 1 | D7: =Неделя!D7 -> 1 | E7: =Неделя!E7 -> 0 | F7: =Неделя!F7 -> 0 | G7: =Неделя!G7 -> 0 | H7: =Неделя!J7 -> 1
A8: =Неделя!A8 -> чунунок к. Мяготина-2x180 | B8: =Неделя!B8 -> 4.14 | C8: =Неделя!C8 -> 2 | D8: =Неделя!D8 -> 0 | E8: =Неделя!E8 -> 0 | F8: =Неделя!F8 -> 0 | G8: =Неделя!G8 -> 0 | H8: =Неделя!J8 -> 1
A9: =Неделя!A9 -> Сбер академия 2х150 коричнев стар | B9: =Неделя!B9 -> 2.55 | C9: =Неделя!C9 -> 0 | D9: =Неделя!D9 -> 2 | E9: =Неделя!E9 -> 0 | F9: =Неделя!F9 -> 0 | G9: =Неделя!G9 -> 0 | H9: =Неделя!J9 -> 1
A10: =Неделя!A10 -> Сбер красина 2х150 | B10: =Неделя!B10 -> 2.55 | C10: =Неделя!C10 -> 0 | D10: =Неделя!D10 -> 2 | E10: =Неделя!E10 -> 0 | F10: =Неделя!F10 -> 0 | G10: =Неделя!G10 -> 0 | H10: =Неделя!J10 -> 1
A11: =Неделя!A11 -> сбербанк гоголя 98-3ий вход 1 х 150 | B11: =Неделя!B11 -> 1.275 | C11: =Неделя!C11 -> 2 | D11: =Неделя!D11 -> 5 | E11: =Неделя!E11 -> 0 | F11: =Неделя!F11 -> 0 | G11: =Неделя!G11 -> 0 | H11: =Неделя!J11 -> 1
A12: =Неделя!A12 -> сбербанк гоголя103- 2х150 коричневые | B12: =Неделя!B12 -> 2.55 | C12: =Неделя!C12 -> 0 | D12: =Неделя!D12 -> 2 | E12: =Неделя!E12 -> 0 | F12: =Неделя!F12 -> 0 | G12: =Неделя!G12 -> 0 | H12: =Неделя!J12 -> 1
... A70: =Неделя!A70 -> 0 | B70: =Неделя!B70 -> 0 | C70: =Неделя!C70 -> 0 | D70: =Неделя!D70 -> 0 | E70: =Неделя!E70 -> 0 | F70: =Неделя!F70 -> 0 | G70: =Неделя!G70 -> 0 | H70: =Неделя!J70 -> 0
A71: =Неделя!A71 -> мтс гоголя 53 - 180серый 1 | C71: =Неделя!C71 -> 1 | D71: =Неделя!D71 -> 0 | E71: =Неделя!E71 -> 0 | F71: =Неделя!F71 -> 0 | G71: =Неделя!G71 -> 0 | H71: =Неделя!J71 -> 0
A72: =Неделя!A72 -> МТС Пушкина 150 | C72: =Неделя!C72 -> 0 | D72: =Неделя!D72 -> 0 | E72: =Неделя!E72 -> 0 | F72: =Неделя!F72 -> 0 | G72: =Неделя!G72 -> 0 | H72: =Неделя!J72 -> 0
A73: =Неделя!A73 -> мтс Пушкина 167- 150 | B73: =Неделя!B73 -> 1.275 | C73: =Неделя!C73 -> 0 | D73: =Неделя!D73 -> 1 | E73: =Неделя!E73 -> 0 | F73: =Неделя!F73 -> 0 | G73: =Неделя!G73 -> 0 | H73: =Неделя!J73 -> 1
A74: =Неделя!A74 -> Промсвязь банк 150,180 | B74: =Неделя!B74 -> 3.345 | C74: =Неделя!C74 -> 1 | D74: =Неделя!D74 -> 1 | E74: =Неделя!E74 -> 0 | F74: =Неделя!F74 -> 0 | G74: =Неделя!G74 -> 0 | H74: =Неделя!J74 -> 1
A75: =Неделя!A75 -> Ресторан СОЛО Куйбышева | B75: =Неделя!B75 -> 1.257 | C75: =Неделя!C75 -> 0 | D75: =Неделя!D75 -> 1 | E75: =Неделя!E75 -> 0 | F75: =Неделя!F75 -> 0 | G75: =Неделя!G75 -> 0 | H75: =Неделя!J75 -> 1
A76: =Неделя!A76 -> Теле2 гоголя-150 резаный | C76: =Неделя!C76 -> 0 | D76: =Неделя!D76 -> 1 | E76: =Неделя!E76 -> 0 | F76: =Неделя!F76 -> 0 | G76: =Неделя!G76 -> 0 | H76: =Неделя!J76 -> 0
A77: =Неделя!A77 -> Томография К. маркса | B77: =Неделя!B77 -> 1.275 | C77: =Неделя!C77 -> 0 | D77: =Неделя!D77 -> 1 | E77: =Неделя!E77 -> 0 | F77: =Неделя!F77 -> 0 | G77: =Неделя!G77 -> 0 | H77: =Неделя!J77 -> 1
A78: =Неделя!A78 -> Фикс прайс к.мяготина 180*2 | B78: =Неделя!B78 -> 4.14 | C78: =Неделя!C78 -> 2 | D78: =Неделя!D78 -> 0 | E78: =Неделя!E78 -> 0 | F78: =Неделя!F78 -> 0 | G78: =Неделя!G78 -> 0 | H78: =Неделя!J78 -> 1
A79: =Неделя!A79 -> 0 | B79: =Неделя!B79 -> 0 | C79: =Неделя!C79 -> 0 | D79: =Неделя!D79 -> 0 | E79: =Неделя!E79 -> 0 | F79: =Неделя!F79 -> 0 | G79: =Неделя!G79 -> 0 | H79: =Неделя!J79 -> 0
A80: =Неделя!A80 -> Фикс советска40-2х180 | C80: =Неделя!C80 -> 2 | D80: =Неделя!D80 -> 0 | E80: =Неделя!E80 -> 0 | F80: =Неделя!F80 -> 0 | G80: =Неделя!G80 -> 0 | H80: =Неделя!J80 -> 0
A81: =Неделя!A81 -> Чистый квартал 150, 80х80 | C81: =Неделя!C81 -> 0 | D81: =Неделя!D81 -> 1 | E81: =Неделя!E81 -> 1 | F81: =Неделя!F81 -> 0 | G81: =Неделя!G81 -> 0 | H81: =Неделя!J81 -> 0
A82: =Неделя!A82 -> Япоки гоголя-180 | C82: =Неделя!C82 -> 1 | D82: =Неделя!D82 -> 0 | E82: =Неделя!E82 -> 0 | F82: =Неделя!F82 -> 0 | G82: =Неделя!G82 -> 0 | H82: =Неделя!J82 -> 0
A83: =Неделя!A83 -> 4 сезона ленина-180 | B83: =Неделя!B83 -> 2.07 | C83: =Неделя!C83 -> 1 | D83: =Неделя!D83 -> 0 | E83: =Неделя!E83 -> 0 | F83: =Неделя!F83 -> 0 | G83: =Неделя!G83 -> 0 | H83: =Неделя!J83 -> 1
A84: =Неделя!A84 -> Александрит 150 рез | C84: =Неделя!C84 -> 0 | D84: =Неделя!D84 -> 1 | E84: =Неделя!E84 -> 0 | F84: =Неделя!F84 -> 0 | G84: =Неделя!G84 -> 0 | H84: =Неделя!J84 -> 0
A85: =Неделя!A85 -> Алеф-банк 150 НОЯБРЬ | C85: =Неделя!C85 -> 0 | D85: =Неделя!D85 -> 1 | E85: =Неделя!E85 -> 0 | F85: =Неделя!F85 -> 0 | G85: =Неделя!G85 -> 0 | H85: =Неделя!J85 -> 0
A86: =Неделя!A86 -> Альфастрахование 2х180 | B86: =Неделя!B86 -> 4.14 | C86: =Неделя!C86 -> 2 | D86: =Неделя!D86 -> 0 | E86: =Неделя!E86 -> 0 | F86: =Неделя!F86 -> 0 | G86: =Неделя!G86 -> 0 | H86: =Неделя!J86 -> 0
A87: =Неделя!A87 -> Аптека советская ленина 150 | B87: =Неделя!B87 -> 1.275 | C87: =Неделя!C87 -> 0 | D87: =Неделя!D87 -> 1 | E87: =Неделя!E87 -> 0 | F87: =Неделя!F87 -> 0 | G87: =Неделя!G87 -> 0 | H87: =Неделя!J87 -> 1
A88: =Неделя!A88 -> Баден Ленина-200 старый | B88: =Неделя!B88 -> 2.07 | C88: =Неделя!C88 -> 1 | D88: =Неделя!D88 -> 0 | E88: =Неделя!E88 -> 0 | F88: =Неделя!F88 -> 0 | G88: =Неделя!G88 -> 0 | H88: =Неделя!J88 -> 1
A89: =Неделя!A89 -> 0 | C89: =Неделя!C89 -> 0 | D89: =Неделя!D89 -> 0 | E89: =Неделя!E89 -> 0 | F89: =Неделя!F89 -> 0 | G89: =Неделя!G89 -> 0 | H89: =Неделя!J89 -> 0
A90: =Неделя!A90 -> Банк курган Гоголя 180 | C90: =Неделя!C90 -> 1 | D90: =Неделя!D90 -> 0 | E90: =Неделя!E90 -> 0 | F90: =Неделя!F90 -> 0 | G90: =Неделя!G90 -> 0 | H90: =Неделя!J90 -> 0
A91: =Неделя!A91 -> Банк курган площадь 150 сер. 1шт. | C91: =Неделя!C91 -> 0 | D91: =Неделя!D91 -> 1 | E91: =Неделя!E91 -> 0 | F91: =Неделя!F91 -> 0 | G91: =Неделя!G91 -> 0 | H91: =Неделя!J91 -> 0
A92: =Неделя!A92 -> Банк России 150 2шт | C92: =Неделя!C92 -> 0 | D92: =Неделя!D92 -> 0 | E92: =Неделя!E92 -> 0 | F92: =Неделя!F92 -> 1 | G92: =Неделя!G92 -> 0 | H92: =Неделя!J92 -> 0
A93: =Неделя!A93 -> Бенетон 150 | C93: =Неделя!C93 -> 0 | D93: =Неделя!D93 -> 1 | E93: =Неделя!E93 -> 0 | F93: =Неделя!F93 -> 0 | G93: =Неделя!G93 -> 0 | H93: =Неделя!J93 -> 0
A94: =Неделя!A94 -> Вояж володарская150 сер. 1 шт.нов. | C94: =Неделя!C94 -> 0 | D94: =Неделя!D94 -> 1 | E94: =Неделя!E94 -> 0 | F94: =Неделя!F94 -> 0 | G94: =Неделя!G94 -> 0 | H94: =Неделя!J94 -> 0
A95: =Неделя!A95 -> Газпроммежрегионгаз Гоголя 98 1x150 | C95: =Неделя!C95 -> 0 | D95: =Неделя!D95 -> 0 | E95: =Неделя!E95 -> 0 | F95: =Неделя!F95 -> 0 | G95: =Неделя!G95 -> 0 | H95: =Неделя!J95 -> 0
A96: =Неделя!A96 -> газпроммежрегионгаз- 5х150 | C96: =Неделя!C96 -> 0 | D96: =Неделя!D96 -> 0 | E96: =Неделя!E96 -> 0 | F96: =Неделя!F96 -> 0 | G96: =Неделя!G96 -> 0 | H96: =Неделя!J96 -> 0
A97: =Неделя!A97 -> Джинса ленина 150 | C97: =Неделя!C97 -> 0 | D97: =Неделя!D97 -> 1 | E97: =Неделя!E97 -> 0 | F97: =Неделя!F97 -> 0 | G97: =Неделя!G97 -> 0 | H97: =Неделя!J97 -> 0
...

Sheet среда
B1: =Неделя!A1 -> Велес гоголя 180 | C1: =Неделя!B1 -> 2.07 | D1: =Неделя!C1 -> 1 | E1: =Неделя!D1 -> 0 | F1: =Неделя!E1 -> 0 | G1: =Неделя!F1 -> 0 | H1: =Неделя!G1 -> 0 | I1: =Неделя!K1 -> 1
B2: =Неделя!A2 -> Велес красина 180 | C2: =Неделя!B2 -> 2.07 | D2: =Неделя!C2 -> 1 | E2: =Неделя!D2 -> 0 | F2: =Неделя!E2 -> 0 | G2: =Неделя!F2 -> 0 | H2: =Неделя!G2 -> 0 | I2: =Неделя!K2 -> 1
B3: =Неделя!A3 -> департамент финансов советская 66-150 резаный | C3: =Неделя!B3 -> 1.275 | D3: =Неделя!C3 -> 0 | E3: =Неделя!D3 -> 1 | F3: =Неделя!E3 -> 0 | G3: =Неделя!F3 -> 0 | H3: =Неделя!G3 -> 0 | I3: =Неделя!K3 -> 1
B4: =Неделя!A4 -> метрополис к. Маркса -2x180, 2x150 | C4: =Неделя!B4 -> 6.69 | D4: =Неделя!C4 -> 2 | E4: =Неделя!D4 -> 2 | F4: =Неделя!E4 -> 0 | G4: =Неделя!F4 -> 0 | H4: =Неделя!G4 -> 0 | I4: =Неделя!K4 -> 1
B5: =Неделя!A5 -> метрополис Москва-2х180 | C5: =Неделя!B5 -> 4.14 | D5: =Неделя!C5 -> 2 | E5: =Неделя!D5 -> 0 | F5: =Неделя!E5 -> 0 | G5: =Неделя!F5 -> 0 | H5: =Неделя!G5 -> 0 | I5: =Неделя!K5 -> 1
B6: =Неделя!A6 -> МТС ленина 6 180 | C6: =Неделя!B6 -> 2.07 | D6: =Неделя!C6 -> 1 | E6: =Неделя!D6 -> 0 | F6: =Неделя!E6 -> 0 | G6: =Неделя!F6 -> 0 | H6: =Неделя!G6 -> 0 | I6: =Неделя!K6 -> 1
B7: =Неделя!A7 -> пальмира Ленина 5- 200 новый 150 нов | C7: =Неделя!B7 -> 3.345 | D7: =Неделя!C7 -> 1 | E7: =Неделя!D7 -> 1 | F7: =Неделя!E7 -> 0 | G7: =Неделя!F7 -> 0 | H7: =Неделя!G7 -> 0 | I7: =Неделя!K7 -> 1
B8: =Неделя!A8 -> чунунок к. Мяготина-2x180 | C8: =Неделя!B8 -> 4.14 | D8: =Неделя!C8 -> 2 | E8: =Неделя!D8 -> 0 | F8: =Неделя!E8 -> 0 | G8: =Неделя!F8 -> 0 | H8: =Неделя!G8 -> 0 | I8: =Неделя!K8 -> 1
B9: =Неделя!A9 -> Сбер академия 2х150 коричнев стар | C9: =Неделя!B9 -> 2.55 | D9: =Неделя!C9 -> 0 | E9: =Неделя!D9 -> 2 | F9: =Неделя!E9 -> 0 | G9: =Неделя!F9 -> 0 | H9: =Неделя!G9 -> 0 | I9: =Неделя!K9 -> 1
B10: =Неделя!A10 -> Сбер красина 2х150 | C10: =Неделя!B10 -> 2.55 | D10: =Неделя!C10 -> 0 | E10: =Неделя!D10 -> 2 | F10: =Неделя!E10 -> 0 | G10: =Неделя!F10 -> 0 | H10: =Неделя!G10 -> 0 | I10: =Неделя!K10 -> 1
B11: =Неделя!A11 -> сбербанк гоголя 98-3ий вход 1 х 150 | C11: =Неделя!B11 -> 1.275 | D11: =Неделя!C11 -> 2 | E11: =Неделя!D11 -> 5 | F11: =Неделя!E11 -> 0 | G11: =Неделя!F11 -> 0 | H11: =Неделя!G11 -> 0 | I11: =Неделя!K11 -> 1
B12: =Неделя!A12 -> сбербанк гоголя103- 2х150 коричневые | C12: =Неделя!B12 -> 2.55 | D12: =Неделя!C12 -> 0 | E12: =Неделя!D12 -> 2 | F12: =Неделя!E12 -> 0 | G12: =Неделя!F12 -> 0 | H12: =Неделя!G12 -> 0 | I12: =Неделя!K12 -> 1
B13: =Неделя!A86 -> Альфастрахование 2х180 | C13: =Неделя!B86 -> 4.14 | D13: =Неделя!C86 -> 2 | E13: =Неделя!D86 -> 0 | F13: =Неделя!E86 -> 0 | G13: =Неделя!F86 -> 0 | H13: =Неделя!G86 -> 0 | I13: =Неделя!K86 -> 1
B14: =Неделя!A89 -> 0 | C14: =Неделя!B89 -> 0 | D14: =Неделя!C89 -> 0 | E14: =Неделя!D89 -> 0 | F14: =Неделя!E89 -> 0 | G14: =Неделя!F89 -> 0 | H14: =Неделя!G89 -> 0 | I14: =Неделя!K89 -> 0
B15: =Неделя!A13 -> Велес дзержинского 180 | C15: =Неделя!B13 -> 2.07 | D15: =Неделя!C13 -> 1 | E15: =Неделя!D13 -> 0 | F15: =Неделя!E13 -> 0 | G15: =Неделя!F13 -> 0 | H15: =Неделя!G13 -> 0 | I15: =Неделя!K13 -> 1
B16: =Неделя!A14 -> велес юбилейный-150 новый | C16: =Неделя!B14 -> 1.275 | D16: =Неделя!C14 -> 0 | E16: =Неделя!D14 -> 1 | F16: =Неделя!E14 -> 0 | G16: =Неделя!F14 -> 0 | H16: =Неделя!G14 -> 0 | I16: =Неделя!K14 -> 1
B17: =Неделя!A94 -> Вояж володарская150 сер. 1 шт.нов. | C17: =Неделя!B94 -> 1.275 | D17: =Неделя!C94 -> 0 | E17: =Неделя!D94 -> 1 | F17: =Неделя!E94 -> 0 | G17: =Неделя!F94 -> 0 | H17: =Неделя!G94 -> 0 | I17: =Неделя!K94 -> 1
B18: =Неделя!A15 -> газпроммежрегионгаз- 2x150, 180 | C18: =Неделя!B15 -> 4.62 | D18: =Неделя!C15 -> 1 | E18: =Неделя!D15 -> 0 | F18: =Неделя!E15 -> 0 | G18: =Неделя!F15 -> 0 | H18: =Неделя!G15 -> 0 | I18: =Неделя!K15 -> 1
B19: =Неделя!A97 -> Джинса ленина 150 | C19: =Неделя!B97 -> 1.275 | D19: =Неделя!C97 -> 0 | E19: =Неделя!D97 -> 1 | F19: =Неделя!E97 -> 0 | G19: =Неделя!F97 -> 0 | H19: =Неделя!G97 -> 0 | I19: =Неделя!K97 -> 1
B20: =Неделя!A100 -> Ив роше Ленина180 | C20: =Неделя!B100 -> 2.07 | D20: =Неделя!C100 -> 1 | E20: =Неделя!D100 -> 0 | F20: =Неделя!E100 -> 0 | G20: =Неделя!F100 -> 0 | H20: =Неделя!G100 -> 0 | I20: =Неделя!K100 -> 1
B21: =Неделя!A106 -> Каменный цветок омская 101 150 нов | C21: =Неделя!B106 -> 1.275 | D21: =Неделя!C106 -> 0 | E21: =Неделя!D106 -> 1 | F21: =Неделя!E106 -> 0 | G21: =Неделя!F106 -> 0 | H21: =Неделя!G106 -> 0 | I21: =Неделя!K106 -> 1
B22: =Неделя!A153 -> Каре Куйбышева 150 | C22: =Неделя!B153 -> 1.275 | D22: =Неделя!C153 -> 0 | E22: =Неделя!D153 -> 0 | F22: =Неделя!E153 -> 0 | G22: =Неделя!F153 -> 0 | H22: =Неделя!G153 -> 0 | I22: =Неделя!K153 -> 1
B23: =Неделя!A110 -> Карэ ленина 150 коричневый | C23: =Неделя!B110 -> 1.275 | D23: =Неделя!C110 -> 0 | E23: =Неделя!D110 -> 1 | F23: =Неделя!E110 -> 0 | G23: =Неделя!F110 -> 0 | H23: =Неделя!G110 -> 0 | I23: =Неделя!K110 -> 1
B24: =Неделя!A16 -> Кижк 400 рез, 180 | C24: =Неделя!B16 -> 6.07 | D24: =Неделя!C16 -> 1 | E24: =Неделя!D16 -> 0 | F24: =Неделя!E16 -> 0 | G24: =Неделя!F16 -> 1 | H24: =Неделя!G16 -> 0 | I24: =Неделя!K16 -> 1
B25: =Неделя!A17 -> кодак Кирова-150 старые | C25: =Неделя!B17 -> 1.275 | D25: =Неделя!C17 -> 0 | E25: =Неделя!D17 -> 1 | F25: =Неделя!E17 -> 0 | G25: =Неделя!F17 -> 0 | H25: =Неделя!G17 -> 0 | I25: =Неделя!K17 -> 1
B26: =Неделя!A113 -> 0 | C26: =Неделя!B113 -> 0 | D26: =Неделя!C113 -> 0 | E26: =Неделя!D113 -> 0 | F26: =Неделя!E113 -> 0 | G26: =Неделя!F113 -> 0 | H26: =Неделя!G113 -> 0 | I26: =Неделя!K113 -> 0
B27: =Неделя!A114 -> 0 | C27: =Неделя!B114 -> 0 | D27: =Неделя!C114 -> 0 | E27: =Неделя!D114 -> 0 | F27: =Неделя!E114 -> 0 | G27: =Неделя!F114 -> 0 | H27: =Неделя!G114 -> 0 | I27: =Неделя!K114 -> 0
B28: =Неделя!A18 -> мегаблин гоголя-180 | C28: =Неделя!B18 -> 2.07 | D28: =Неделя!C18 -> 1 | E28: =Неделя!D18 -> 0 | F28: =Неделя!E18 -> 0 | G28: =Неделя!F18 -> 0 | H28: =Неделя!G18 -> 0 | I28: =Неделя!K18 -> 1
B29: =Неделя!A19 -> Монетка гоголя 103 -180 | C29: =Неделя!B19 -> 2.07 | D29: =Неделя!C19 -> 1 | E29: =Неделя!D19 -> 0 | F29: =Неделя!E19 -> 0 | G29: =Неделя!F19 -> 0 | H29: =Неделя!G19 -> 0 | I29: =Неделя!K19 -> 1
B30: =Неделя!A20 -> Монетка кирова 180 | C30: =Неделя!B20 -> 2.07 | D30: =Неделя!C20 -> 1 | E30: =Неделя!D20 -> 0 | F30: =Неделя!E20 -> 0 | G30: =Неделя!F20 -> 0 | H30: =Неделя!G20 -> 0 | I30: =Неделя!K20 -> 1
B31: =Неделя!A21 -> Монетка красина 180 | C31: =Неделя!B21 -> 2.07 | D31: =Неделя!C21 -> 1 | E31: =Неделя!D21 -> 0 | F31: =Неделя!E21 -> 0 | G31: =Неделя!F21 -> 0 | H31: =Неделя!G21 -> 0 | I31: =Неделя!K21 -> 1
B32: =Неделя!A22 -> Монетка пушкина 49-180 | C32: =Неделя!B22 -> 2.07 | D32: =Неделя!C22 -> 1 | E32: =Неделя!D22 -> 0 | F32: =Неделя!E22 -> 0 | G32: =Неделя!F22 -> 0 | H32: =Неделя!G22 -> 0 | I32: =Неделя!K22 -> 1
B33: =Неделя!A23 -> Монтка Ленина М Горько 180 | C33: =Неделя!B23 -> 2.07 | D33: =Неделя!C23 -> 1 | E33: =Неделя!D23 -> 0 | F33: =Неделя!E23 -> 0 | G33: =Неделя!F23 -> 0 | H33: =Неделя!G23 -> 0 | I33: =Неделя!K23 -> 1
B34: =Неделя!A24 -> Мясной к. маркса 150 рез | C34: =Неделя!B24 -> 1.275 | D34: =Неделя!C24 -> 0 | E34: =Неделя!D24 -> 1 | F34: =Неделя!E24 -> 0 | G34: =Неделя!F24 -> 0 | H34: =Неделя!G24 -> 0 | I34: =Неделя!K24 -> 1
B35: =Неделя!A25 -> Мясной советская 39 180 | C35: =Неделя!B25 -> 2.07 | D35: =Неделя!C25 -> 1 | E35: =Неделя!D25 -> 0 | F35: =Неделя!E25 -> 0 | G35: =Неделя!F25 -> 0 | H35: =Неделя!G25 -> 0 | I35: =Неделя!K25 -> 1
B36: =Неделя!A36 -> Авангард банк красина 180 сер. 1 шт | C36: =Неделя!B36 -> 2.07 | D36: =Неделя!C36 -> 1 | E36: =Неделя!D36 -> 0 | F36: =Неделя!E36 -> 0 | G36: =Неделя!F36 -> 0 | H36: =Неделя!G36 -> 0 | I36: =Неделя!K36 -> 0
B37: =Неделя!A37 -> Альфа банк гоголя 180 | C37: =Неделя!B37 -> 2.07 | D37: =Неделя!C37 -> 1 | E37: =Неделя!D37 -> 0 | F37: =Неделя!E37 -> 0 | G37: =Неделя!F37 -> 0 | H37: =Неделя!G37 -> 0 | I37: =Неделя!K37 -> 0
B38: =Неделя!A38 -> Альфа банк Гоголя-красина 150 сер.нов.1 шт. | C38: =Неделя!B38 -> 1.275 | D38: =Неделя!C38 -> 0 | E38: =Неделя!D38 -> 1 | F38: =Неделя!E38 -> 0 | G38: =Неделя!F38 -> 0 | H38: =Неделя!G38 -> 0 | I38: =Неделя!K38 -> 0
B39: =Неделя!A39 -> Альфа мед гоголя-2х180 | C39: =Неделя!B39 -> 4.14 | D39: =Неделя!C39 -> 2 | E39: =Неделя!D39 -> 0 | F39: =Неделя!E39 -> 0 | G39: =Неделя!F39 -> 0 | H39: =Неделя!G39 -> 0 | I39: =Неделя!K39 -> 0
B40: =Неделя!A40 -> Альфа мед к.маркса -2х180,(ц.зд. Женщины, кометология) | C40: =Неделя!B40 -> 4.14 | D40: =Неделя!C40 -> 2 | E40: =Неделя!D40 -> 0 | F40: =Неделя!E40 -> 0 | G40: =Неделя!F40 -> 0 | H40: =Неделя!G40 -> 0 | I40: =Неделя!K40 -> 0
...

Sheet четверг
A1: =Неделя!A1 -> Велес гоголя 180 | B1: =Неделя!B1 -> 2.07 | C1: =Неделя!C1 -> 1 | D1: =Неделя!D1 -> 0 | E1: =Неделя!E1 -> 0 | F1: =Неделя!F1 -> 0 | G1: =Неделя!G1 -> 0 | H1: =Неделя!L1 -> 1
A2: =Неделя!A2 -> Велес красина 180 | B2: =Неделя!B2 -> 2.07 | C2: =Неделя!C2 -> 1 | D2: =Неделя!D2 -> 0 | E2: =Неделя!E2 -> 0 | F2: =Неделя!F2 -> 0 | G2: =Неделя!G2 -> 0 | H2: =Неделя!L2 -> 1
A3: =Неделя!A3 -> департамент финансов советская 66-150 резаный | B3: =Неделя!B3 -> 1.275 | C3: =Неделя!C3 -> 0 | D3: =Неделя!D3 -> 1 | E3: =Неделя!E3 -> 0 | F3: =Неделя!F3 -> 0 | G3: =Неделя!G3 -> 0 | H3: =Неделя!L3 -> 1
A4: =Неделя!A4 -> метрополис к. Маркса -2x180, 2x150 | B4: =Неделя!B4 -> 6.69 | C4: =Неделя!C4 -> 2 | D4: =Неделя!D4 -> 2 | E4: =Неделя!E4 -> 0 | F4: =Неделя!F4 -> 0 | G4: =Неделя!G4 -> 0 | H4: =Неделя!L4 -> 1
A5: =Неделя!A5 -> метрополис Москва-2х180 | B5: =Неделя!B5 -> 4.14 | C5: =Неделя!C5 -> 2 | D5: =Неделя!D5 -> 0 | E5: =Неделя!E5 -> 0 | F5: =Неделя!F5 -> 0 | G5: =Неделя!G5 -> 0 | H5: =Неделя!L5 -> 1
A6: =Неделя!A6 -> МТС ленина 6 180 | B6: =Неделя!B6 -> 2.07 | C6: =Неделя!C6 -> 1 | D6: =Неделя!D6 -> 0 | E6: =Неделя!E6 -> 0 | F6: =Неделя!F6 -> 0 | G6: =Неделя!G6 -> 0 | H6: =Неделя!L6 -> 1
A7: =Неделя!A7 -> пальмира Ленина 5- 200 новый 150 нов | B7: =Неделя!B7 -> 3.345 | C7: =Неделя!C7 -> 1 | D7: =Неделя!D7 -> 1 | E7: =Неделя!E7 -> 0 | F7: =Неделя!F7 -> 0 | G7: =Неделя!G7 -> 0 | H7: =Неделя!L7 -> 1
A8: =Неделя!A8 -> чунунок к. Мяготина-2x180 | B8: =Неделя!B8 -> 4.14 | C8: =Неделя!C8 -> 2 | D8: =Неделя!D8 -> 0 | E8: =Неделя!E8 -> 0 | F8: =Неделя!F8 -> 0 | G8: =Неделя!G8 -> 0 | H8: =Неделя!L8 -> 1
A9: =Неделя!A9 -> Сбер академия 2х150 коричнев стар | B9: =Неделя!B9 -> 2.55 | C9: =Неделя!C9 -> 0 | D9: =Неделя!D9 -> 2 | E9: =Неделя!E9 -> 0 | F9: =Неделя!F9 -> 0 | G9: =Неделя!G9 -> 0 | H9: =Неделя!L9 -> 1
A10: =Неделя!A10 -> Сбер красина 2х150 | B10: =Неделя!B10 -> 2.55 | C10: =Неделя!C10 -> 0 | D10: =Неделя!D10 -> 2 | E10: =Неделя!E10 -> 0 | F10: =Неделя!F10 -> 0 | G10: =Неделя!G10 -> 0 | H10: =Неделя!L10 -> 1
A11: =Неделя!A11 -> сбербанк гоголя 98-3ий вход 1 х 150 | B11: =Неделя!B11 -> 1.275 | C11: =Неделя!C11 -> 2 | D11: =Неделя!D11 -> 5 | E11: =Неделя!E11 -> 0 | F11: =Неделя!F11 -> 0 | G11: =Неделя!G11 -> 0 | H11: =Неделя!L11 -> 0
A12: =Неделя!A12 -> сбербанк гоголя103- 2х150 коричневые | B12: =Неделя!B12 -> 2.55 | C12: =Неделя!C12 -> 0 | D12: =Неделя!D12 -> 2 | E12: =Неделя!E12 -> 0 | F12: =Неделя!F12 -> 0 | G12: =Неделя!G12 -> 0 | H12: =Неделя!L12 -> 1
... A152: =Неделя!A152 -> SoupRamen 180 | B152: =Неделя!B152 -> 2.07 | C152: =Неделя!C152 -> 1 | D152: =Неделя!D152 -> 0 | E152: =Неделя!E152 -> 0 | F152: =Неделя!F152 -> 0 | G152: =Неделя!G152 -> 0 | H152: =Неделя!L152 -> 1
A153: =Неделя!A154 -> 0 | B153: =SUBTOTAL(9,B1:B152) -> 140.215 | C153: =Неделя!C154 -> 180 | D153: =Неделя!D154 -> 150 | E153: =Неделя!E154 -> рез | F153: =Неделя!F154 -> 400 | G153: =Неделя!G154 -> 250 | H153: =Неделя!L154 -> чт
A154: =Неделя!A155 -> 0 | B154: =Неделя!B155 -> 98.51 | C154: =Неделя!C155 -> 180 | D154: =Неделя!D155 -> 150 | E154: =Неделя!E155 -> рез | F154: =Неделя!F155 -> 400 | G154: =Неделя!G155 -> 250 | H154: =Неделя!L155 -> 0
A155: =Неделя!A156 -> 0 | B155: =Неделя!B156 -> 0 | C155: =Неделя!C156 -> 28 | D155: =Неделя!D156 -> 23 | E155: =Неделя!E156 -> 3 | F155: =Неделя!F156 -> 1 | G155: =Неделя!G156 -> 1 | H155: =Неделя!L156 -> 0
A156: =Неделя!A157 -> 0 | B156: =Неделя!B157 -> 0 | C156: =Неделя!C157 -> 0 | D156: =Неделя!D157 -> 0 | E156: =Неделя!E157 -> 0 | F156: =Неделя!F157 -> 0 | G156: =Неделя!G157 -> 0 | H156: =Неделя!L157 -> 0
A157: =Неделя!A158 -> 0 | B157: =Неделя!B158 -> 0 | C157: =Неделя!C158 -> 0 | D157: =Неделя!D158 -> 0 | E157: =Неделя!E158 -> 0 | F157: =Неделя!F158 -> 0 | G157: =Неделя!G158 -> 0 | H157: =Неделя!L158 -> 0
A158: =Неделя!A159 -> 0 | B158: =Неделя!B159 -> 0 | C158: =Неделя!C159 -> 0 | D158: =Неделя!D159 -> 0 | E158: =Неделя!E159 -> 0 | F158: =Неделя!F159 -> 0 | G158: =Неделя!G159 -> 0 | H158: =Неделя!L159 -> 0
A159: =Неделя!A160 -> 0 | B159: =Неделя!B160 -> 0 | C159: =Неделя!C160 -> 0 | D159: =Неделя!D160 -> 0 | E159: =Неделя!E160 -> 0 | F159: =Неделя!F160 -> 0 | G159: =Неделя!G160 -> 0 | H159: =Неделя!L160 -> 0
A160: =Неделя!A161 -> 0 | B160: =Неделя!B161 -> 0 | C160: =Неделя!C161 -> 0 | D160: =Неделя!D161 -> 0 | E160: =Неделя!E161 -> 0 | F160: =Неделя!F161 -> 0 | G160: =Неделя!G161 -> 0 | H160: =Неделя!L161 -> 0
A161: =Неделя!A162 -> 0 | B161: =Неделя!B162 -> 0 | C161: =Неделя!C162 -> 0 | D161: =Неделя!D162 -> 0 | E161: =Неделя!E162 -> 0 | F161: =Неделя!F162 -> 0 | G161: =Неделя!G162 -> 0 | H161: =Неделя!L162 -> 0
A162: =Неделя!A163 -> 0 | B162: =Неделя!B163 -> 0 | C162: =Неделя!C163 -> 0 | D162: =Неделя!D163 -> 0 | E162: =Неделя!E163 -> 0 | F162: =Неделя!F163 -> 0 | G162: =Неделя!G163 -> 0 | H162: =Неделя!L163 -> 0
A163: =Неделя!A164 -> 0 | B163: =Неделя!B164 -> 0 | C163: =Неделя!C164 -> 0 | D163: =Неделя!D164 -> 0 | E163: =Неделя!E164 -> 0 | F163: =Неделя!F164 -> 0 | G163: =Неделя!G164 -> 0 | H163: =Неделя!L164 -> 0
A164: =Неделя!A165 -> 0 | B164: =Неделя!B165 -> 0 | C164: =Неделя!C165 -> 0 | D164: =Неделя!D165 -> 0 | E164: =Неделя!E165 -> 0 | F164: =Неделя!F165 -> 0 | G164: =Неделя!G165 -> 0 | H164: =Неделя!L165 -> 0
A165: =Неделя!A166 -> 0 | B165: =Неделя!B166 -> 0 | C165: =Неделя!C166 -> 0 | D165: =Неделя!D166 -> 0 | E165: =Неделя!E166 -> 0 | F165: =Неделя!F166 -> 0 | G165: =Неделя!G166 -> 0 | H165: =Неделя!L166 -> 0
... A213: =Неделя!A214 -> 0 | B213: =Неделя!B214 -> 0 | C213: =Неделя!C214 -> 0 | D213: =Неделя!D214 -> 0 | E213: =Неделя!E214 -> 0 | F213: =Неделя!F214 -> 0 | G213: =Неделя!G214 -> 0 | H213: =Неделя!L214 -> 0

Sheet пятница
A1: =Неделя!A1 -> Велес гоголя 180 | B1: =Неделя!B1 -> 2.07 | C1: =Неделя!C1 -> 1 | D1: =Неделя!D1 -> 0 | E1: =Неделя!E1 -> 0 | F1: =Неделя!F1 -> 0 | G1: =Неделя!G1 -> 0 | H1: =Неделя!M1 -> 1
A2: =Неделя!A2 -> Велес красина 180 | B2: =Неделя!B2 -> 2.07 | C2: =Неделя!C2 -> 1 | D2: =Неделя!D2 -> 0 | E2: =Неделя!E2 -> 0 | F2: =Неделя!F2 -> 0 | G2: =Неделя!G2 -> 0 | H2: =Неделя!M2 -> 1
A3: =Неделя!A3 -> департамент финансов советская 66-150 резаный | B3: =Неделя!B3 -> 1.275 | C3: =Неделя!C3 -> 0 | D3: =Неделя!D3 -> 1 | E3: =Неделя!E3 -> 0 | F3: =Неделя!F3 -> 0 | G3: =Неделя!G3 -> 0 | H3: =Неделя!M3 -> 1
A4: =Неделя!A4 -> метрополис к. Маркса -2x180, 2x150 | B4: =Неделя!B4 -> 6.69 | C4: =Неделя!C4 -> 2 | D4: =Неделя!D4 -> 2 | E4: =Неделя!E4 -> 0 | F4: =Неделя!F4 -> 0 | G4: =Неделя!G4 -> 0 | H4: =Неделя!M4 -> 1
A5: =Неделя!A5 -> метрополис Москва-2х180 | B5: =Неделя!B5 -> 4.14 | C5: =Неделя!C5 -> 2 | D5: =Неделя!D5 -> 0 | E5: =Неделя!E5 -> 0 | F5: =Неделя!F5 -> 0 | G5: =Неделя!G5 -> 0 | H5: =Неделя!M5 -> 1
A6: =Неделя!A6 -> МТС ленина 6 180 | B6: =Неделя!B6 -> 2.07 | C6: =Неделя!C6 -> 1 | D6: =Неделя!D6 -> 0 | E6: =Неделя!E6 -> 0 | F6: =Неделя!F6 -> 0 | G6: =Неделя!G6 -> 0 | H6: =Неделя!M6 -> 1
A7: =Неделя!A7 -> пальмира Ленина 5- 200 новый 150 нов | B7: =Неделя!B7 -> 3.345 | C7: =Неделя!C7 -> 1 | D7: =Неделя!D7 -> 1 | E7: =Неделя!E7 -> 0 | F7: =Неделя!F7 -> 0 | G7: =Неделя!G7 -> 0 | H7: =Неделя!M7 -> 1
A8: =Неделя!A8 -> чунунок к. Мяготина-2x180 | B8: =Неделя!B8 -> 4.14 | C8: =Неделя!C8 -> 2 | D8: =Неделя!D8 -> 0 | E8: =Неделя!E8 -> 0 | F8: =Неделя!F8 -> 0 | G8: =Неделя!G8 -> 0 | H8: =Неделя!M8 -> 1
A9: =Неделя!A9 -> Сбер академия 2х150 коричнев стар | B9: =Неделя!B9 -> 2.55 | C9: =Неделя!C9 -> 0 | D9: =Неделя!D9 -> 2 | E9: =Неделя!E9 -> 0 | F9: =Неделя!F9 -> 0 | G9: =Неделя!G9 -> 0 | H9: =Неделя!M9 -> 0
A10: =Неделя!A10 -> Сбер красина 2х150 | B10: =Неделя!B10 -> 2.55 | C10: =Неделя!C10 -> 0 | D10: =Неделя!D10 -> 2 | E10: =Неделя!E10 -> 0 | F10: =Неделя!F10 -> 0 | G10: =Неделя!G10 -> 0 | H10: =Неделя!M10 -> 0
A11: =Неделя!A11 -> сбербанк гоголя 98-3ий вход 1 х 150 | B11: =Неделя!B11 -> 1.275 | C11: =Неделя!C11 -> 2 | D11: =Неделя!D11 -> 5 | E11: =Неделя!E11 -> 0 | F11: =Неделя!F11 -> 0 | G11: =Неделя!G11 -> 0 | H11: =Неделя!M11 -> 0
A12: =Неделя!A12 -> сбербанк гоголя103- 2х150 коричневые | B12: =Неделя!B12 -> 2.55 | C12: =Неделя!C12 -> 0 | D12: =Неделя!D12 -> 2 | E12: =Неделя!E12 -> 0 | F12: =Неделя!F12 -> 0 | G12: =Неделя!G12 -> 0 | H12: =Неделя!M12 -> 0
... A152: =Неделя!A152 -> SoupRamen 180 | B152: =Неделя!B152 -> 2.07 | C152: =Неделя!C152 -> 1 | D152: =Неделя!D152 -> 0 | E152: =Неделя!E152 -> 0 | F152: =Неделя!F152 -> 0 | G152: =Неделя!G152 -> 0 | H152: =Неделя!M152 -> 0
A153: =Неделя!A154 -> 0 | B153: =SUBTOTAL(9,B1:B152) -> 133.352 | C153: =Неделя!C154 -> 180 | D153: =Неделя!D154 -> 150 | E153: =Неделя!E154 -> рез | F153: =Неделя!F154 -> 400 | G153: =Неделя!G154 -> 250 | H153: =Неделя!M154 -> пт
A154: =Неделя!A155 -> 0 | B154: =Неделя!B155 -> 98.51 | C154: =Неделя!C155 -> 180 | D154: =Неделя!D155 -> 150 | E154: =Неделя!E155 -> рез | F154: =Неделя!F155 -> 400 | G154: =Неделя!G155 -> 250 | H154: =Неделя!M155 -> 0
A155: =Неделя!A156 -> 0 | B155: =Неделя!B156 -> 0 | C155: =Неделя!C156 -> 28 | D155: =Неделя!D156 -> 23 | E155: =Неделя!E156 -> 3 | F155: =Неделя!F156 -> 1 | G155: =Неделя!G156 -> 1 | H155: =Неделя!M156 -> 0
A156: =Неделя!A157 -> 0 | B156: =Неделя!B157 -> 0 | C156: =Неделя!C157 -> 0 | D156: =Неделя!D157 -> 0 | E156: =Неделя!E157 -> 0 | F156: =Неделя!F157 -> 0 | G156: =Неделя!G157 -> 0 | H156: =Неделя!M157 -> 0
A157: =Неделя!A158 -> 0 | B157: =Неделя!B158 -> 0 | C157: =Неделя!C158 -> 0 | D157: =Неделя!D158 -> 0 | E157: =Неделя!E158 -> 0 | F157: =Неделя!F158 -> 0 | G157: =Неделя!G158 -> 0 | H157: =Неделя!M158 -> 0
A158: =Неделя!A159 -> 0 | B158: =Неделя!B159 -> 0 | C158: =Неделя!C159 -> 0 | D158: =Неделя!D159 -> 0 | E158: =Неделя!E159 -> 0 | F158: =Неделя!F159 -> 0 | G158: =Неделя!G159 -> 0 | H158: =Неделя!M159 -> 0
A159: =Неделя!A160 -> 0 | B159: =Неделя!B160 -> 0 | C159: =Неделя!C160 -> 0 | D159: =Неделя!D160 -> 0 | E159: =Неделя!E160 -> 0 | F159: =Неделя!F160 -> 0 | G159: =Неделя!G160 -> 0 | H159: =Неделя!M160 -> 0
A160: =Неделя!A161 -> 0 | B160: =Неделя!B161 -> 0 | C160: =Неделя!C161 -> 0 | D160: =Неделя!D161 -> 0 | E160: =Неделя!E161 -> 0 | F160: =Неделя!F161 -> 0 | G160: =Неделя!G161 -> 0 | H160: =Неделя!M161 -> 0
A161: =Неделя!A162 -> 0 | B161: =Неделя!B162 -> 0 | C161: =Неделя!C162 -> 0 | D161: =Неделя!D162 -> 0 | E161: =Неделя!E162 -> 0 | F161: =Неделя!F162 -> 0 | G161: =Неделя!G162 -> 0 | H161: =Неделя!M162 -> 0
A162: =Неделя!A163 -> 0 | B162: =Неделя!B163 -> 0 | C162: =Неделя!C163 -> 0 | D162: =Неделя!D163 -> 0 | E162: =Неделя!E163 -> 0 | F162: =Неделя!F163 -> 0 | G162: =Неделя!G163 -> 0 | H162: =Неделя!M163 -> 0
A163: =Неделя!A164 -> 0 | B163: =Неделя!B164 -> 0 | C163: =Неделя!C164 -> 0 | D163: =Неделя!D164 -> 0 | E163: =Неделя!E164 -> 0 | F163: =Неделя!F164 -> 0 | G163: =Неделя!G164 -> 0 | H163: =Неделя!M164 -> 0
A164: =Неделя!A165 -> 0 | B164: =Неделя!B165 -> 0 | C164: =Неделя!C165 -> 0 | D164: =Неделя!D165 -> 0 | E164: =Неделя!E165 -> 0 | F164: =Неделя!F165 -> 0 | G164: =Неделя!G165 -> 0 | H164: =Неделя!M165 -> 0
A165: =Неделя!A166 -> 0 | B165: =Неделя!B166 -> 0 | C165: =Неделя!C166 -> 0 | D165: =Неделя!D166 -> 0 | E165: =Неделя!E166 -> 0 | F165: =Неделя!F166 -> 0 | G165: =Неделя!G166 -> 0 | H165: =Неделя!M166 -> 0
... A327: =Неделя!A328 -> 0 | B327: =Неделя!B328 -> 0 | C327: =Неделя!C328 -> 0 | D327: =Неделя!D328 -> 0 | E327: =Неделя!E328 -> 0 | F327: =Неделя!F328 -> 0 | G327: =Неделя!G328 -> 0 | H327: =Неделя!M328 -> 0

Sheet ПН
D1: 180 | E1: 150 | F1: 60*80 | G1: 400 | H1: 250
A2: 1 | B2: сбербанк гоголя 98-3ий вход 1 х 150 | C2: 1.275 | D2: 2 | E2: 4 | F2: 0 | G2: 0 | H2: 0
A3: 1 | B3: сбербанк гоголя 98-1 вх 3Х150 коричневые | C3: 3.825 | D3: 0 | E3: 0 | F3: 0 | G3: 0 | H3: 0
A4: 1 | B4: сбербанк гоголя 98-2ой вход 2х180 | C4: 4.14 | D4: 0 | E4: 0 | F4: 0 | G4: 0 | H4: 0
A5: 2 | B5: газпроммежрегионгаз- 2x150, 180 | C5: 4.62 | D5: 1 | E5: 2 | F5: 0 | G5: 0 | H5: 0
A6: 3 | B6: прогресс Пролетарская-180, 60x80 | C6: 3.345 | D6: 1 | E6: 0 | F6: 1 | G6: 0 | H6: 0
A7: 4 | B7: метрополис к. Маркса -2x180, 2x150 | C7: 6.69 | D7: 2 | E7: 2 | F7: 0 | G7: 0 | H7: 0
A8: 5 | B8: Мясной советская 39 180 | C8: 2.07 | D8: 1 | E8: 0 | F8: 0 | G8: 0 | H8: 0
A9: 6 | B9: Магнит советская 39 180 | C9: 2.07 | D9: 1 | E9: 0 | F9: 0 | G9: 0 | H9: 0
A10: 7 | B10: Магнит советская 40 180 | C10: 2.07 | D10: 1 | E10: 0 | F10: 0 | G10: 0 | H10: 0
A11: 8 | B11: Фикс советска40-2х180 | C11: 4.14 | D11: 2 | E11: 0 | F11: 0 | G11: 0 | H11: 0
A12: 9 | B12: департамент финансов советская 66-150 резаный | C12: 1.275 | D12: 0 | E12: 1 | F12: 0 | G12: 0 | H12: 0
A13: 10 | B13: прогресс советская 180, 150 новые | C13: 3.345 | D13: 1 | E13: 1 | F13: 0 | G13: 0 | H13: 0
... A27: 23 | B27: Сбер красина 2х150 | C27: 2.55 | D27: 0 | E27: 2 | F27: 0 | G27: 0 | H27: 0
C28: =SUM(C2:C27) -> 73.11 | D28: =SUM(D2:D27) -> 23 | E28: =SUM(E2:E27) -> 19 | F28: =SUM(F2:F27) -> 1
G30: 400 | H30: 250
A31: 24 | B31: Газпром банк гоголя-180 | C31: 2.07 | D31: 1 | E31: 0 | F31: 0 | G31: 0 | H31: 0
A32: 25 | B32: Япоки гоголя-180 | C32: 2.07 | D32: 1 | E32: 0 | F32: 0 | G32: 0 | H32: 0
A33: 26 | B33: Теле2 гоголя-150 резаный | C33: 1.275 | D33: 0 | E33: 1 | F33: 0 | G33: 0 | H33: 0
A34: 27 | B34: Монетка гоголя 103 -180 | C34: 2.07 | D34: 1 | E34: 0 | F34: 0 | G34: 0 | H34: 0
A35: 28 | B35: сбербанк гоголя103- 2х150 коричневые | C35: 2.55 | D35: 0 | E35: 2 | F35: 0 | G35: 0 | H35: 0
A36: 29 | B36: мтс гоголя 53 - 180серый 1 | C36: 2.07 | D36: 1 | E36: 0 | F36: 0 | G36: 0 | H36: 0
A37: 30 | B37: Альфа банк гоголя 180 | C37: 2.07 | D37: 1 | E37: 0 | F37: 0 | G37: 0 | H37: 0
A38: 31 | B38: Аптека гоголя 37-150 | C38: 1.275 | D38: 0 | E38: 1 | F38: 0 | G38: 0 | H38: 0
A39: 32 | B39: Курган Доставка | C39: 1.275 | D39: 0 | E39: 1 | F39: 0 | G39: 0 | H39: 0
A40: 33 | B40: Чистый квартал 150, 80х80 | C40: 2.55 | D40: 0 | E40: 1 | F40: 1 | G40: 0 | H40: 0
A41: 34 | B41: Сбер академия 2х150 коричнев стар | C41: 2.55 | D41: 0 | E41: 2 | F41: 0 | G41: 0 | H41: 0
A42: 35 | B42: Монетка кирова 180 | C42: 2.07 | D42: 1 | E42: 0 | F42: 0 | G42: 0 | H42: 0
... A51: 43 | B51: Банк России 180 2шт | C51: 4.14 | D51: 2 | E51: 2 | F51: 0 | G51: 0 | H51: 0
A52: 43.5 | B52: кардио центр 180 1шт | C52: 2.07 | D52: 1
A53: 44 | B53: МТС ленина 6 180 | C53: 2.07 | D53: 1 | E53: 0 | F53: 0 | G53: 0 | H53: 0
A54: 45 | B54: Монтка Ленина М Горько 180 | C54: 2.07 | D54: 1 | E54: 0 | F54: 0 | G54: 0 | H54: 0
A55: 46 | B55: Яхонт ленина 150 | C55: 1.275 | D55: 0 | E55: 1 | F55: 0 | G55: 0 | H55: 0
A56: 47 | B56: Пальмира гоголя 150 | C56: 1.275 | D56: 0 | E56: 1 | F56: 0 | G56: 0 | H56: 0
A57: 48 | B57: Велес гоголя 180 | C57: 2.07 | D57: 1 | E57: 0 | F57: 0 | G57: 0 | H57: 0
A58: 49 | B58: Магнит гоголя 66-180 | C58: 2.07 | D58: 1 | E58: 0 | F58: 0 | G58: 0 | H58: 0
A59: 50 | B59: Баон 150 | C59: 1.275 | D59: 0 | E59: 1 | F59: 0 | G59: 0 | H59: 0
A60: 51 | B60: Летуаль 180 | C60: 2.07 | D60: 1 | E60: 0 | F60: 0 | G60: 0 | H60: 0
A61: 52 | B61: Магнит Гоголя 76 180 | C61: 2.07 | D61: 1 | E61: 0 | F61: 0 | G61: 0 | H61: 0
A62: 54 | B62: Жизнь март пролетарская -180 | C62: 2.07 | D62: 1 | E62: 0 | F62: 0 | G62: 0 | H62: 0
...

Sheet ВТ
A1: 1 | B1: сбербанк гоголя 98-1 вх 3Х150 коричневые | C1: 3.825 | D1: 0 | E1: 0 | F1: 0 | G1: 0 | H1: 0 | I1: 1
A2: 1 | B2: сбербанк гоголя 98-2ой вход 2х180 | C2: 4.14 | D2: 0 | E2: 0 | F2: 0 | G2: 0 | H2: 0 | I2: 1
A3: 1 | B3: сбербанк гоголя 98-3ий вход 1 х 150 | C3: 1.275 | D3: 2 | E3: 5 | F3: 0 | G3: 0 | H3: 0 | I3: 1
A4: 2 | B4: метрополис к. Маркса -2x180, 2x150 | C4: 6.69 | D4: 2 | E4: 2 | F4: 0 | G4: 0 | H4: 0 | I4: 1
A5: 3 | B5: МТС ленина 6 180 | C5: 2.07 | D5: 1 | E5: 0 | F5: 0 | G5: 0 | H5: 0 | I5: 1
A6: 4 | B6: пальмира Ленина 5- 200 новый 150 нов | C6: 3.345 | D6: 1 | E6: 1 | F6: 0 | G6: 0 | H6: 0 | I6: 1
A7: 5 | B7: Прайм фитнес клуб 2х150 новые | C7: 2.55 | D7: 0 | E7: 2 | F7: 0 | G7: 0 | H7: 0 | I7: 1
A8: 6 | B8: Аннушка куйбышева 180 | C8: 2.07 | D8: 1 | E8: 0 | F8: 0 | G8: 0 | H8: 0 | I8: 1
A9: 7 | B9: Втб куйбышева 180 | C9: 2.07 | D9: 1 | E9: 0 | F9: 0 | G9: 0 | H9: 0 | I9: 1
A10: 8 | B10: Атлант кирова 250 | C10: 3.7 | D10: 0 | E10: 0 | F10: 1 | G10: 0 | H10: 0 | I10: 1
B11: Ресторан СОЛО Куйбышева | C11: 1.257 | D11: 0 | E11: 1 | F11: 0 | G11: 0 | H11: 0 | I11: 1
A12: 9 | B12: Офис центр куйбышева-красина 180,150рез | C12: 3.345 | D12: 1 | E12: 1 | F12: 0 | G12: 0 | H12: 0 | I12: 1
A13: 10 | B13: Буше красина 150 нов | C13: 1.275 | D13: 0 | E13: 1 | F13: 0 | G13: 0 | H13: 0 | I13: 1
A14: 11 | B14: департамент финансов советская 66-150 резаный | C14: 1.275 | D14: 0 | E14: 1 | F14: 0 | G14: 0 | H14: 0 | I14: 1
B15: Мегафон советская 2х150 рез | C15: 2.55 | D15: 0 | E15: 2 | F15: 0 | G15: 0 | H15: 0 | I15: 1
A16: 12 | B16: Авангард банк красина 180 сер. 1 шт | C16: 2.07 | D16: 1 | E16: 0 | F16: 0 | G16: 0 | H16: 0 | I16: 1
A17: 13 | B17: Альфа банк Гоголя-красина 150 сер.нов.1 шт. | C17: 1.275 | D17: 0 | E17: 1 | F17: 0 | G17: 0 | H17: 0 | I17: 1
A18: 14 | B18: Промсвязь банк 150,180 | C18: 3.345 | D18: 1 | E18: 1 | F18: 0 | G18: 0 | H18: 0 | I18: 1
A19: 15 | B19: Ингострах 2х150 | C19: 2.55 | D19: 0 | E19: 2 | F19: 0 | G19: 0 | H19: 0 | I19: 1
A20: 17 | B20: Велес красина 180 | C20: 2.07 | D20: 1 | E20: 0 | F20: 0 | G20: 0 | H20: 0 | I20: 1
A21: 18 | B21: Сбер академия 2х150 коричнев стар | C21: 2.55 | D21: 0 | E21: 2 | F21: 0 | G21: 0 | H21: 0 | I21: 1
A22: 19 | B22: Платон к.Мяготина 180 | C22: 2.07 | D22: 1 | E22: 0 | F22: 0 | G22: 0 | H22: 0 | I22: 1
A23: 20 | B23: Фикс прайс к.мяготина 180*2 | C23: 4.14 | D23: 2 | E23: 0 | F23: 0 | G23: 0 | H23: 0 | I23: 1
A24: 21 | B24: Консультант + васильева 7 240старый | C24: 2.7 | D24: 1 | E24: 0 | F24: 0 | G24: 0 | H24: 0 | I24: 1
A25: 22 | B25: чунунок к. Мяготина-2x180 | C25: 4.14 | D25: 2 | E25: 0 | F25: 0 | G25: 0 | H25: 0 | I25: 1
A26: 23 | B26: магнит красина 180 | C26: 2.07 | D26: 1 | E26: 0 | F26: 0 | G26: 0 | H26: 0 | I26: 1
A27: 24 | B27: Аптека гоголя 9-150 | C27: 1.275 | D27: 0 | E27: 1 | F27: 0 | G27: 0 | H27: 0 | I27: 1
... A29: 26 | B29: Сбер красина 2х150 | C29: 2.55 | D29: 0 | E29: 2 | F29: 0 | G29: 0 | H29: 0 | I29: 1
C30: =SUM(C1:C29) -> 78.382
A32: 26.5 | B32: сбербанк гоголя103- 2х150 коричневые | C32: 2.55 | D32: 0 | E32: 2 | F32: 0 | G32: 0 | H32: 0 | I32: 1
A33: 27 | B33: Сибирский газовик володарского 65, 150 сер. 3 шт | C33: 3.825 | D33: 0 | E33: 3 | F33: 0 | G33: 0 | H33: 0 | I33: 1
A34: 28 | B34: Магнит Володарского 180 | C34: 2.07 | D34: 1 | E34: 0 | F34: 0 | G34: 0 | H34: 0 | I34: 1
A35: 29 | B35: Магнит К.маркса 180 | C35: 2.07 | D35: 1 | E35: 0 | F35: 0 | G35: 0 | H35: 0 | I35: 1
A36: 30 | B36: Карэ к. Маркса 46 3х150 нов кор | C36: 3.825 | D36: 0 | E36: 3 | F36: 0 | G36: 0 | H36: 0 | I36: 1
A37: 31 | B37: Альфа мед к.маркса -2х180,(ц.зд. Женщины, кометология) | C37: 4.14 | D37: 2 | E37: 0 | F37: 0 | G37: 0 | H37: 0 | I37: 1
A38: 32 | B38: Томография К. маркса | C38: 1.275 | D38: 0 | E38: 1 | F38: 0 | G38: 0 | H38: 0 | I38: 1
A39: 33 | B39: М.горького 40 180*2 | C39: 4.14 | D39: 2 | E39: 0 | F39: 0 | G39: 0 | H39: 0 | I39: 1
A40: 34 | B40: Карэ гараж К.Маркса 60а 150 | C40: 1.275 | D40: 0 | E40: 1 | F40: 0 | G40: 0 | H40: 0 | I40: 1
A41: 35 | B41: Друзья друзей 2х150 | C41: 2.55 | D41: 2 | E41: 0 | F41: 0 | G41: 0 | H41: 0 | I41: 1
A42: 36 | B42: Буше горького 150 | C42: 1.275 | D42: 0 | E42: 1 | F42: 0 | G42: 0 | H42: 0 | I42: 1
...

Sheet СР
A1: 1 | B1: сбербанк гоголя 98-1 вх 3Х150 коричневые | C1: 3.825 | D1: 0 | E1: 0 | F1: 0 | G1: 0 | H1: 0 | I1: 1
A2: 1 | B2: сбербанк гоголя 98-2ой вход 2х180 | C2: 4.14 | D2: 0 | E2: 0 | F2: 0 | G2: 0 | H2: 0 | I2: 1
A3: 1 | B3: сбербанк гоголя 98-3ий вход 1 х 150 | C3: 1.275 | D3: 2 | E3: 5 | F3: 0 | G3: 0 | H3: 0 | I3: 1
A4: 2 | B4: газпроммежрегионгаз- 2x150, 180 | C4: 4.62 | D4: 1 | E4: 0 | F4: 0 | G4: 0 | H4: 0 | I4: 1
A5: 3 | B5: прогресс Пролетарская-180, 60x80 | C5: 3.345 | D5: 1 | E5: 0 | F5: 1 | G5: 0 | H5: 0 | I5: 1
A6: 4 | B6: метрополис к. Маркса -2x180, 2x150 | C6: 6.69 | D6: 2 | E6: 2 | F6: 0 | G6: 0 | H6: 0 | I6: 1
A7: 4.5 | B7: Отель Централь, ресторан 180х3 | C7: 6.21 | D7: 3 | E7: 0 | F7: 0 | G7: 0 | H7: 0 | I7: 1
A8: 5 | B8: Велес красина 180 | C8: 2.07 | D8: 1 | E8: 0 | F8: 0 | G8: 0 | H8: 0 | I8: 1
A9: 6 | B9: Сбер академия 2х150 коричнев стар | C9: 2.55 | D9: 0 | E9: 2 | F9: 0 | G9: 0 | H9: 0 | I9: 1
B10: Чистый квартал 150, 80х80 | C10: 2.55
A11: 7 | B11: чунунок к. Мяготина-2x180 | C11: 4.14 | D11: 2 | E11: 0 | F11: 0 | G11: 0 | H11: 0 | I11: 1
A12: 8 | B12: Монетка пушкина 49-180 | C12: 2.07 | D12: 1 | E12: 0 | F12: 0 | G12: 0 | H12: 0 | I12: 1
A13: 9 | B13: пальмира юбилейный-180 НОВЫЙ | C13: 2.07 | D13: 1 | E13: 0 | F13: 0 | G13: 0 | H13: 0 | I13: 1
A14: 10 | B14: велес юбилейный-150 новый | C14: 1.275 | D14: 0 | E14: 1 | F14: 0 | G14: 0 | H14: 0 | I14: 1
A15: 11 | B15: Япошка Юбилейный 150 резаный | C15: 1.275 | D15: 0 | E15: 1 | F15: 0 | G15: 0 | H15: 0 | I15: 1
A16: 12 | B16: метрополис Москва-2х180 | C16: 4.14 | D16: 2 | E16: 0 | F16: 0 | G16: 0 | H16: 0 | I16: 1
A17: 13 | B17: Тп 2х180 | C17: 4.14 | D17: 2 | E17: 0 | F17: 0 | G17: 0 | H17: 0 | I17: 1
A18: 14 | B18: Неил хаус 150 новый | C18: 1.275 | D18: 0 | E18: 1 | F18: 0 | G18: 0 | H18: 0 | I18: 1
A19: 15 | B19: Монетка красина 180 | C19: 2.07 | D19: 1 | E19: 0 | F19: 0 | G19: 0 | H19: 0 | I19: 1
A20: 16 | B20: Сбер красина 2х150 | C20: 2.55 | D20: 0 | E20: 2 | F20: 0 | G20: 0 | H20: 0 | I20: 1
A21: 17 | B21: Франческо донни 150 рез. | C21: 1.275 | D21: 0 | E21: 1 | F21: 0 | G21: 0 | H21: 0 | I21: 1
A22: 18 | B22: Монетка кирова 180 | C22: 2.07 | D22: 1 | E22: 0 | F22: 0 | G22: 0 | H22: 0 | I22: 1
... A25: 21 | B25: Хлеб да мясо 150 резаный хороший | C25: 1.275 | D25: 0 | E25: 1 | F25: 0 | G25: 0 | H25: 0 | I25: 1
C26: =SUM(C1:C25) -> 70.245
A28: 27.05 | B28: Монетка гоголя 103 -180 | C28: 2.07 | D28: 1 | E28: 0 | F28: 0 | G28: 0 | H28: 0 | I28: 1
A29: 27.1 | B29: сбербанк гоголя103- 2х150 коричневые | C29: 2.55 | D29: 0 | E29: 2 | F29: 0 | G29: 0 | H29: 0 | I29: 1
A30: 27.2 | B30: Вояж володарская150 сер. 1 шт.нов. | C30: 1.275 | D30: 0 | E30: 1 | F30: 0 | G30: 0 | H30: 0 | I30: 1
A31: 27.3 | B31: Платинум володарская150 сер. 1 шт. | C31: 1.275 | D31: 0 | E31: 1 | F31: 0 | G31: 0 | H31: 0 | I31: 1
A32: 27.4 | B32: Мясной к. маркса 150 рез | C32: 1.275 | D32: 0 | E32: 1 | F32: 0 | G32: 0 | H32: 0 | I32: 1
A33: 27.44 | B33: Мясной советская 39 180 | C33: 2.07 | D33: 1 | E33: 0 | F33: 0 | G33: 0 | H33: 0 | I33: 1
A34: 27.45 | B34: Триумф 180 | C34: 2.07 | D34: 1 | E34: 0 | F34: 0 | G34: 0 | H34: 0 | I34: 1
A35: 27.46 | B35: Альфастрахование 2х180 | C35: 4.14 | D35: 2 | E35: 0 | F35: 0 | G35: 0 | H35: 0 | I35: 1
A36: 27.47 | B36: департамент финансов советская 66-150 резаный | C36: 1.275 | D36: 0 | E36: 1 | F36: 0 | G36: 0 | H36: 0 | I36: 1
A37: 27.48 | B37: прогресс советская 180, 150 новые | C37: 3.345 | D37: 1 | E37: 1 | F37: 0 | G37: 0 | H37: 0 | I37: 1
A38: 27.49 | B38: пальмира Ленина 5- 200 новый 150 нов | C38: 3.345 | D38: 1 | E38: 1 | F38: 0 | G38: 0 | H38: 0 | I38: 1
A39: 27.491 | B39: Каре Куйбышева 150 | C39: 1.275 | D39: 0 | E39: 0 | F39: 0 | G39: 0 | H39: 0 | I39: 1
... A50: 37 | B50: Пальмира гоголя 150 | C50: 1.275 | D50: 0 | E50: 1 | F50: 0 | G50: 0 | H50: 0 | I50: 1
A51: 38 | B51: Велес дзержинского 180 | D51: 1 | E51: 0 | F51: 0 | G51: 0 | H51: 0 | I51: 1
A52: 39 | B52: Кижк 400 рез, 180 | D52: 1 | E52: 0 | F52: 0 | G52: 1 | H52: 0 | I52: 1
C53: =SUM(C28:C52) -> 43.17
...

Sheet ЧТ
A1: 1 | B1: сбербанк гоголя 98-1 вх 3Х150 коричневые | D1: 0 | E1: 0 | F1: 0 | G1: 0 | H1: 0 | I1: 1
A2: 2 | B2: Газпроммежрегионгаз Гоголя 98 1x150 | D2: 0 | E2: 0 | F2: 0 | G2: 0 | H2: 0 | I2: 1
A3: 3 | B3: газпроммежрегионгаз- 5х150 | C3: 6.375 | D3: 0 | E3: 0 | F3: 0 | G3: 0 | H3: 0 | I3: 1
A4: 4 | B4: метрополис к. Маркса -2x180, 2x150 | C4: 6.69 | D4: 2 | E4: 2 | F4: 0 | G4: 0 | H4: 0 | I4: 1
A5: 5 | B5: Кардио центр 180 3шт 150 1шт | C5: =2.07*3+1.275 -> 7.485
A6: 7 | B6: Банк России 180 2шт | C6: 4.14 | D6: 2 | E6: 2 | F6: 0 | G6: 0 | H6: 0 | I6: 1
A7: 7.5 | B7: Банк России 150 2шт | C7: 2.55 | D7: 0 | E7: 0 | F7: 0 | G7: 1 | H7: 0 | I7: 1
A8: 8 | B8: департамент финансов советская 66-150 резаный | C8: 1.275 | D8: 0 | E8: 1 | F8: 0 | G8: 0 | H8: 0 | I8: 1
A9: 9 | B9: Джулия советская 180 | C9: 2.07 | D9: 1 | E9: 0 | F9: 0 | G9: 0 | H9: 0 | I9: 1
A10: 10 | B10: Фикс советска40-2х180 | C10: 4.14 | D10: 2 | E10: 0 | F10: 0 | G10: 0 | H10: 0 | I10: 1
A11: 11 | B11: Магнит советская 40 180 | C11: 2.07 | D11: 1 | E11: 0 | F11: 0 | G11: 0 | H11: 0 | I11: 1
A12: 12 | B12: Магнит советская 39 180 | C12: 2.07 | D12: 1 | E12: 0 | F12: 0 | G12: 0 | H12: 0 | I12: 1
A13: 13 | B13: инвитро красина-3х150 новые | C13: 3.825 | D13: 0 | E13: 3 | F13: 0 | G13: 0 | H13: 0 | I13: 1
A14: 14 | B14: Велес красина 180 | C14: 2.07 | D14: 1 | E14: 0 | F14: 0 | G14: 0 | H14: 0 | I14: 1
A15: 15 | B15: Аптека пушкина 91-2х150 | C15: 2.55 | D15: 0 | E15: 2 | F15: 0 | G15: 0 | H15: 0 | I15: 1
A16: 16 | B16: Сбер академия 2х150 коричнев стар | C16: 2.55 | D16: 0 | E16: 2 | F16: 0 | G16: 0 | H16: 0 | I16: 1
A17: 17 | B17: Мисс т 150 сер, нов. 1шт. | C17: 1.275 | D17: 0 | E17: 1 | F17: 0 | G17: 0 | H17: 0 | I17: 1
A18: 18 | B18: Швейный мир 2-60х80 | C18: 2.55 | D18: 0 | E18: 0 | F18: 2 | G18: 0 | H18: 0 | I18: 1
A19: 19 | B19: Чистый квартал 150, 80х80 | D19: 0 | E19: 1 | F19: 1 | G19: 0 | H19: 0 | I19: 1
A20: 20 | B20: чунунок к. Мяготина-2x180 | C20: 4.14 | D20: 2 | E20: 0 | F20: 0 | G20: 0 | H20: 0 | I20: 1
A21: 21 | B21: Комиссоныч юбилейный-150 рез. | C21: 1.275 | D21: 0 | E21: 1 | F21: 0 | G21: 0 | H21: 0 | I21: 1
A22: 22 | B22: Разговоры ЦПКОИ 180 | C22: 2.07 | D22: 1 | E22: 0 | F22: 0 | G22: 0 | H22: 0 | I22: 1
A23: 23 | B23: метрополис Москва-2х180 | C23: 4.14 | D23: 2 | E23: 0 | F23: 0 | G23: 0 | H23: 0 | I23: 1
A24: 23.5 | B24: Сбер красина 2х150 | C24: 2.55 | D24: 0 | E24: 2 | F24: 0 | G24: 0 | H24: 0 | I24: 1
C25: =SUM(C1:C24) -> 67.86
A27: 29 | B27: совкомбанк гоголя-180 | C27: 2.07 | D27: 1 | E27: 0 | F27: 0 | G27: 0 | H27: 0 | I27: 1
A28: 29.4 | B28: Газпром банк гоголя-180 | C28: 2.07 | D28: 1 | E28: 0 | F28: 0 | G28: 0 | H28: 0 | I28: 1
A29: 29.44 | B29: Япоки гоголя-180 | C29: 2.07 | D29: 1 | E29: 0 | F29: 0 | G29: 0 | H29: 0 | I29: 1
A30: 29.5 | B30: Теле2 гоголя-150 резаный | C30: 1.275 | D30: 0 | E30: 1 | F30: 0 | G30: 0 | H30: 0 | I30: 1
A31: 30 | B31: сбербанк гоголя103- 2х150 коричневые | C31: 2.55 | D31: 0 | E31: 2 | F31: 0 | G31: 0 | H31: 0 | I31: 1
A32: 31 | B32: Алеф-банк 150 НОЯБРЬ | C32: 1.275 | D32: 0 | E32: 1 | F32: 0 | G32: 0 | H32: 0 | I32: 1
A33: 32 | B33: SoupRamen 180 | C33: 2.07 | D33: 1 | E33: 0 | F33: 0 | G33: 0 | H33: 0 | I33: 1
A34: 33 | B34: Стиляги площадь серый новый 150+150 | C34: 2.55 | D34: 0 | E34: 2 | F34: 0 | G34: 0 | H34: 0 | I34: 1
A35: 34 | B35: мтс гоголя 53 - 180серый 1 | C35: 2.07 | D35: 1 | E35: 0 | F35: 0 | G35: 0 | H35: 0 | I35: 1
A36: 35 | B36: Банк курган площадь 150 сер. 1шт. | C36: 1.275 | D36: 0 | E36: 1 | F36: 0 | G36: 0 | H36: 0 | I36: 1
A37: 36 | B37: Александрит 150 рез | C37: 1.275 | D37: 0 | E37: 1 | F37: 0 | G37: 0 | H37: 0 | I37: 1
A38: 37 | B38: Альфа банк гоголя 180 | C38: 2.07 | D38: 1 | E38: 0 | F38: 0 | G38: 0 | H38: 0 | I38: 1
... A61: 56 | B61: Джулия пролетарская 200 хороший | C61: 2.07 | D61: 1 | E61: 0 | F61: 0 | G61: 0 | H61: 0 | I61: 1
B62: 0 | C62: =SUM(C27:C61) -> 70.915 | D62: 180 | E62: 150 | F62: рез | G62: 400 | H62: 250 | I62: чт

Sheet ПТ
